Workbook
Name 목록_병해충조회용: '참고 사항'!$A$18:$A$47
Name 목록_정보구분: '참고 사항'!$B$18:$B$47
Name 목록_병해충구분: '참고 사항'!$C$18:$C$47
Name 목록_방제구분: '참고 사항'!$D$18:$D$47
Name 목록_학교보유: '참고 사항'!$E$18:$E$47
Name 목록_혼용가능여부: '참고 사항'!$F$18:$F$47
Name 목록_제형: '참고 사항'!$G$18:$G$47
Name 목록_살포방법: '참고 사항'!$H$18:$H$47

Sheet 병해충 방제 가이드
A1: 파프리카 병해충 방제 가이드 · 연암대학교 스마트팜 유리온실
A2: 공통 주의 ▶ 같은 작용기작(코드)을 연속 사용하면 저항성이 생기니, 2회 이상 살포 시 2~4순위로 바꿔가며 로테이션 · 확인 안 된 약제 조합은 섞지 않는 것이 원칙 · 노란색 = 학교(연암대) 보유 약제
A4: ① 병해충 선택 ▶ | B4: 꽃노랑총채벌레 | F4: ◀ 칸을 누르고 ▼ 목록에서 선택 | J4: 병해충 구분 | K4: =IF(SUMPRODUCT(('전체 방제 정보'!$E$2:$E$3000=$B$4)*('전체 방제 정보'!$B$2:$B$3000="추천 약제(로테이션)"))=0,"",INDEX('전체 방제 정보'!$D$2:$D$3000,SUMPRODUCT(('전체 방제 정보'!$E$2:$E$3000=$B$4)*('전체 방제 정보'!$B$2:$B$3000="추천 약제(로테이션)")*(ROW('전체 방제 정보'!$E$2:$E$3000)-1)*('전체 방제 정보'!$F$2:$F$3000=1)))) | M4: 유기농업자재(보조) | O4: =IF(COUNTIFS('전체 방제 정보'!$E$2:$E$3000,$B$4,'전체 방제 정보'!$B$2:$B$3000,"유기농업자재")=0,"해당 없음",COUNTIFS('전체 방제 정보'!$E$2:$E$3000,$B$4,'전체 방제 정보'!$B$2:$B$3000,"유기농업자재")&"건 — 아래 표에서 [방제 구분] = 유기농업자재 확인")
A5: =IF($B$4="","병해충을 선택하세요",$B$4&CHAR(10)&"→ 적용 약제") | D5: 순위 | E5: 약제명 | F5: 제형 | G5: 학교 보유 | H5: 방제 구분 | I5: 희석배수 | J5: 살포 방법 | K5: 살포 시기 | L5: 수확 전 사용 제한 | M5: 최대 살포 횟수 | N5: 살포 간격 | O5: 주의사항 | P5: 혼용 정보
D6: =IF(SUMPRODUCT(('전체 방제 정보'!$E$2:$E$3000=$B$4)*('전체 방제 정보'!$B$2:$B$3000="추천 약제(로테이션)")*('전체 방제 정보'!$F$2:$F$3000=1)*(ROW('전체 방제 정보'!$E$2:$E$3000)-1))=0,"",1) | E6: =IF(SUMPRODUCT(('전체 방제 정보'!$E$2:$E$3000=$B$4)*('전체 방제 정보'!$B$2:$B$3000="추천 약제(로테이션)")*('전체 방제 정보'!$F$2:$F$3000=1)*(ROW('전체 방제 정보'!$E$2:$E$3000)-1))=0,"",IF(INDEX('전체 방제 정보'!$G$2:$G$3000,SUMPRODUCT(('전체 방제 정보'!$E$2:$E$3000=$B$4)*('전체 방제 정보'!$B$2:$B$3000="추천 약제(로테이션)")*('전체 방제 정보'!$F$2:$F$3000=1)*(ROW('전체 방제 정보'!$E$2:$E$3000)-1)))="","",INDEX('전체 방제 정보'!$G$2:$G$3000,SUMPRODUCT(('전체 방제 정보'!$E$2:$E$3000=$B$4)*('전체 방제 정보'!$B$2:$B$3000="추천 약제(로테이션)")*('전체 방제 정보'!$F$2:$F$3000=1)*(ROW('전체 방제 정보'!$E$2:$E$3000)-1))))) | F6: =IF(SUMPRODUCT(('전체 방제 정보'!$E$2:$E$3000=$B$4)*('전체 방제 정보'!$B$2:$B$3000="추천 약제(로테이션)")*('전체 방제 정보'!$F$2:$F$3000=1)*(ROW('전체 방제 정보'!$E$2:$E$3000)-1))=0,"",IF(INDEX('전체 방제 정보'!$H$2:$H$3000,SUMPRODUCT(('전체 방제 정보'!$E$2:$E$3000=$B$4)*('전체 방제 정보'!$B$2:$B$3000="추천 약제(로테이션)")*('전체 방제 정보'!$F$2:$F$3000=1)*(ROW('전체 방제 정보'!$E$2:$E$3000)-1)))="","",INDEX('전체 방제 정보'!$H$2:$H$3000,SUMPRODUCT(('전체 방제 정보'!$E$2:$E$3000=$B$4)*('전체 방제 정보'!$B$2:$B$3000="추천 약제(로테이션)")*('전체 방제 정보'!$F$2:$F$3000=1)*(ROW('전체 방제 정보'!$E$2:$E$3000)-1))))) | G6: =IF(SUMPRODUCT(('전체 방제 정보'!$E$2:$E$3000=$B$4)*('전체 방제 정보'!$B$2:$B$3000="추천 약제(로테이션)")*('전체 방제 정보'!$F$2:$F$3000=1)*(ROW('전체 방제 정보'!$E$2:$E$3000)-1))=0,"",IF(INDEX('전체 방제 정보'!$I$2:$I$3000,SUMPRODUCT(('전체 방제 정보'!$E$2:$E$3000=$B$4)*('전체 방제 정보'!$B$2:$B$3000="추천 약제(로테이션)")*('전체 방제 정보'!$F$2:$F$3000=1)*(ROW('전체 방제 정보'!$E$2:$E$3000)-1)))="","",INDEX('전체 방제 정보'!$I$2:$I$3000,SUMPRODUCT(('전체 방제 정보'!$E$2:$E$3000=$B$4)*('전체 방제 정보'!$B$2:$B$3000="추천 약제(로테이션)")*('전체 방제 정보'!$F$2:$F$3000=1)*(ROW('전체 방제 정보'!$E$2:$E$3000)-1))))) | H6: =IF(SUMPRODUCT(('전체 방제 정보'!$E$2:$E$3000=$B$4)*('전체 방제 정보'!$B$2:$B$3000="추천 약제(로테이션)")*('전체 방제 정보'!$F$2:$F$3000=1)*(ROW('전체 방제 정보'!$E$2:$E$3000)-1))=0,"",IF(INDEX('전체 방제 정보'!$J$2:$J$3000,SUMPRODUCT(('전체 방제 정보'!$E$2:$E$3000=$B$4)*('전체 방제 정보'!$B$2:$B$3000="추천 약제(로테이션)")*('전체 방제 정보'!$F$2:$F$3000=1)*(ROW('전체 방제 정보'!$E$2:$E$3000)-1)))="","",INDEX('전체 방제 정보'!$J$2:$J$3000,SUMPRODUCT(('전체 방제 정보'!$E$2:$E$3000=$B$4)*('전체 방제 정보'!$B$2:$B$3000="추천 약제(로테이션)")*('전체 방제 정보'!$F$2:$F$3000=1)*(ROW('전체 방제 정보'!$E$2:$E$3000)-1))))) | I6: =IF(SUMPRODUCT(('전체 방제 정보'!$E$2:$E$3000=$B$4)*('전체 방제 정보'!$B$2:$B$3000="추천 약제(로테이션)")*('전체 방제 정보'!$F$2:$F$3000=1)*(ROW('전체 방제 정보'!$E$2:$E$3000)-1))=0,"",IF(INDEX('전체 방제 정보'!$K$2:$K$3000,SUMPRODUCT(('전체 방제 정보'!$E$2:$E$3000=$B$4)*('전체 방제 정보'!$B$2:$B$3000="추천 약제(로테이션)")*('전체 방제 정보'!$F$2:$F$3000=1)*(ROW('전체 방제 정보'!$E$2:$E$3000)-1)))="","",INDEX('전체 방제 정보'!$K$2:$K$3000,SUMPRODUCT(('전체 방제 정보'!$E$2:$E$3000=$B$4)*('전체 방제 정보'!$B$2:$B$3000="추천 약제(로테이션)")*('전체 방제 정보'!$F$2:$F$3000=1)*(ROW('전체 방제 정보'!$E$2:$E$3000)-1))))) | J6: =IF(SUMPRODUCT(('전체 방제 정보'!$E$2:$E$3000=$B$4)*('전체 방제 정보'!$B$2:$B$3000="추천 약제(로테이션)")*('전체 방제 정보'!$F$2:$F$3000=1)*(ROW('전체 방제 정보'!$E$2:$E$3000)-1))=0,"",IF(INDEX('전체 방제 정보'!$L$2:$L$3000,SUMPRODUCT(('전체 방제 정보'!$E$2:$E$3000=$B$4)*('전체 방제 정보'!$B$2:$B$3000="추천 약제(로테이션)")*('전체 방제 정보'!$F$2:$F$3000=1)*(ROW('전체 방제 정보'!$E$2:$E$3000)-1)))="","",INDEX('전체 방제 정보'!$L$2:$L$3000,SUMPRODUCT(('전체 방제 정보'!$E$2:$E$3000=$B$4)*('전체 방제 정보'!$B$2:$B$3000="추천 약제(로테이션)")*('전체 방제 정보'!$F$2:$F$3000=1)*(ROW('전체 방제 정보'!$E$2:$E$3000)-1))))) | K6: =IF(SUMPRODUCT(('전체 방제 정보'!$E$2:$E$3000=$B$4)*('전체 방제 정보'!$B$2:$B$3000="추천 약제(로테이션)")*('전체 방제 정보'!$F$2:$F$3000=1)*(ROW('전체 방제 정보'!$E$2:$E$3000)-1))=0,"",IF(INDEX('전체 방제 정보'!$M$2:$M$3000,SUMPRODUCT(('전체 방제 정보'!$E$2:$E$3000=$B$4)*('전체 방제 정보'!$B$2:$B$3000="추천 약제(로테이션)")*('전체 방제 정보'!$F$2:$F$3000=1)*(ROW('전체 방제 정보'!$E$2:$E$3000)-1)))="","",INDEX('전체 방제 정보'!$M$2:$M$3000,SUMPRODUCT(('전체 방제 정보'!$E$2:$E$3000=$B$4)*('전체 방제 정보'!$B$2:$B$3000="추천 약제(로테이션)")*('전체 방제 정보'!$F$2:$F$3000=1)*(ROW('전체 방제 정보'!$E$2:$E$3000)-1))))) | L6: =IF(SUMPRODUCT(('전체 방제 정보'!$E$2:$E$3000=$B$4)*('전체 방제 정보'!$B$2:$B$3000="추천 약제(로테이션)")*('전체 방제 정보'!$F$2:$F$3000=1)*(ROW('전체 방제 정보'!$E$2:$E$3000)-1))=0,"",IF(INDEX('전체 방제 정보'!$N$2:$N$3000,SUMPRODUCT(('전체 방제 정보'!$E$2:$E$3000=$B$4)*('전체 방제 정보'!$B$2:$B$3000="추천 약제(로테이션)")*('전체 방제 정보'!$F$2:$F$3000=1)*(ROW('전체 방제 정보'!$E$2:$E$3000)-1)))="","",INDEX('전체 방제 정보'!$N$2:$N$3000,SUMPRODUCT(('전체 방제 정보'!$E$2:$E$3000=$B$4)*('전체 방제 정보'!$B$2:$B$3000="추천 약제(로테이션)")*('전체 방제 정보'!$F$2:$F$3000=1)*(ROW('전체 방제 정보'!$E$2:$E$3000)-1))))) | M6: =IF(SUMPRODUCT(('전체 방제 정보'!$E$2:$E$3000=$B$4)*('전체 방제 정보'!$B$2:$B$3000="추천 약제(로테이션)")*('전체 방제 정보'!$F$2:$F$3000=1)*(ROW('전체 방제 정보'!$E$2:$E$3000)-1))=0,"",IF(INDEX('전체 방제 정보'!$O$2:$O$3000,SUMPRODUCT(('전체 방제 정보'!$E$2:$E$3000=$B$4)*('전체 방제 정보'!$B$2:$B$3000="추천 약제(로테이션)")*('전체 방제 정보'!$F$2:$F$3000=1)*(ROW('전체 방제 정보'!$E$2:$E$3000)-1)))="","",INDEX('전체 방제 정보'!$O$2:$O$3000,SUMPRODUCT(('전체 방제 정보'!$E$2:$E$3000=$B$4)*('전체 방제 정보'!$B$2:$B$3000="추천 약제(로테이션)")*('전체 방제 정보'!$F$2:$F$3000=1)*(ROW('전체 방제 정보'!$E$2:$E$3000)-1))))) | N6: =IF(SUMPRODUCT(('전체 방제 정보'!$E$2:$E$3000=$B$4)*('전체 방제 정보'!$B$2:$B$3000="추천 약제(로테이션)")*('전체 방제 정보'!$F$2:$F$3000=1)*(ROW('전체 방제 정보'!$E$2:$E$3000)-1))=0,"",IF(INDEX('전체 방제 정보'!$P$2:$P$3000,SUMPRODUCT(('전체 방제 정보'!$E$2:$E$3000=$B$4)*('전체 방제 정보'!$B$2:$B$3000="추천 약제(로테이션)")*('전체 방제 정보'!$F$2:$F$3000=1)*(ROW('전체 방제 정보'!$E$2:$E$3000)-1)))="","",INDEX('전체 방제 정보'!$P$2:$P$3000,SUMPRODUCT(('전체 방제 정보'!$E$2:$E$3000=$B$4)*('전체 방제 정보'!$B$2:$B$3000="추천 약제(로테이션)")*('전체 방제 정보'!$F$2:$F$3000=1)*(ROW('전체 방제 정보'!$E$2:$E$3000)-1))))) | O6: =IF(SUMPRODUCT(('전체 방제 정보'!$E$2:$E$3000=$B$4)*('전체 방제 정보'!$B$2:$B$3000="추천 약제(로테이션)")*('전체 방제 정보'!$F$2:$F$3000=1)*(ROW('전체 방제 정보'!$E$2:$E$3000)-1))=0,"",IF(INDEX('전체 방제 정보'!$Q$2:$Q$3000,SUMPRODUCT(('전체 방제 정보'!$E$2:$E$3000=$B$4)*('전체 방제 정보'!$B$2:$B$3000="추천 약제(로테이션)")*('전체 방제 정보'!$F$2:$F$3000=1)*(ROW('전체 방제 정보'!$E$2:$E$3000)-1)))="","",INDEX('전체 방제 정보'!$Q$2:$Q$3000,SUMPRODUCT(('전체 방제 정보'!$E$2:$E$3000=$B$4)*('전체 방제 정보'!$B$2:$B$3000="추천 약제(로테이션)")*('전체 방제 정보'!$F$2:$F$3000=1)*(ROW('전체 방제 정보'!$E$2:$E$3000)-1))))) | P6: =IF(SUMPRODUCT(('전체 방제 정보'!$E$2:$E$3000=$B$4)*('전체 방제 정보'!$B$2:$B$3000="추천 약제(로테이션)")*('전체 방제 정보'!$F$2:$F$3000=1)*(ROW('전체 방제 정보'!$E$2:$E$3000)-1))=0,"",IF(INDEX('전체 방제 정보'!$R$2:$R$3000,SUMPRODUCT(('전체 방제 정보'!$E$2:$E$3000=$B$4)*('전체 방제 정보'!$B$2:$B$3000="추천 약제(로테이션)")*('전체 방제 정보'!$F$2:$F$3000=1)*(ROW('전체 방제 정보'!$E$2:$E$3000)-1)))="","",INDEX('전체 방제 정보'!$R$2:$R$3000,SUMPRODUCT(('전체 방제 정보'!$E$2:$E$3000=$B$4)*('전체 방제 정보'!$B$2:$B$3000="추천 약제(로테이션)")*('전체 방제 정보'!$F$2:$F$3000=1)*(ROW('전체 방제 정보'!$E$2:$E$3000)-1)))))
D7: =IF(SUMPRODUCT(('전체 방제 정보'!$E$2:$E$3000=$B$4)*('전체 방제 정보'!$B$2:$B$3000="추천 약제(로테이션)")*('전체 방제 정보'!$F$2:$F$3000=2)*(ROW('전체 방제 정보'!$E$2:$E$3000)-1))=0,"",2) | E7: =IF(SUMPRODUCT(('전체 방제 정보'!$E$2:$E$3000=$B$4)*('전체 방제 정보'!$B$2:$B$3000="추천 약제(로테이션)")*('전체 방제 정보'!$F$2:$F$3000=2)*(ROW('전체 방제 정보'!$E$2:$E$3000)-1))=0,"",IF(INDEX('전체 방제 정보'!$G$2:$G$3000,SUMPRODUCT(('전체 방제 정보'!$E$2:$E$3000=$B$4)*('전체 방제 정보'!$B$2:$B$3000="추천 약제(로테이션)")*('전체 방제 정보'!$F$2:$F$3000=2)*(ROW('전체 방제 정보'!$E$2:$E$3000)-1)))="","",INDEX('전체 방제 정보'!$G$2:$G$3000,SUMPRODUCT(('전체 방제 정보'!$E$2:$E$3000=$B$4)*('전체 방제 정보'!$B$2:$B$3000="추천 약제(로테이션)")*('전체 방제 정보'!$F$2:$F$3000=2)*(ROW('전체 방제 정보'!$E$2:$E$3000)-1))))) | F7: =IF(SUMPRODUCT(('전체 방제 정보'!$E$2:$E$3000=$B$4)*('전체 방제 정보'!$B$2:$B$3000="추천 약제(로테이션)")*('전체 방제 정보'!$F$2:$F$3000=2)*(ROW('전체 방제 정보'!$E$2:$E$3000)-1))=0,"",IF(INDEX('전체 방제 정보'!$H$2:$H$3000,SUMPRODUCT(('전체 방제 정보'!$E$2:$E$3000=$B$4)*('전체 방제 정보'!$B$2:$B$3000="추천 약제(로테이션)")*('전체 방제 정보'!$F$2:$F$3000=2)*(ROW('전체 방제 정보'!$E$2:$E$3000)-1)))="","",INDEX('전체 방제 정보'!$H$2:$H$3000,SUMPRODUCT(('전체 방제 정보'!$E$2:$E$3000=$B$4)*('전체 방제 정보'!$B$2:$B$3000="추천 약제(로테이션)")*('전체 방제 정보'!$F$2:$F$3000=2)*(ROW('전체 방제 정보'!$E$2:$E$3000)-1))))) | G7: =IF(SUMPRODUCT(('전체 방제 정보'!$E$2:$E$3000=$B$4)*('전체 방제 정보'!$B$2:$B$3000="추천 약제(로테이션)")*('전체 방제 정보'!$F$2:$F$3000=2)*(ROW('전체 방제 정보'!$E$2:$E$3000)-1))=0,"",IF(INDEX('전체 방제 정보'!$I$2:$I$3000,SUMPRODUCT(('전체 방제 정보'!$E$2:$E$3000=$B$4)*('전체 방제 정보'!$B$2:$B$3000="추천 약제(로테이션)")*('전체 방제 정보'!$F$2:$F$3000=2)*(ROW('전체 방제 정보'!$E$2:$E$3000)-1)))="","",INDEX('전체 방제 정보'!$I$2:$I$3000,SUMPRODUCT(('전체 방제 정보'!$E$2:$E$3000=$B$4)*('전체 방제 정보'!$B$2:$B$3000="추천 약제(로테이션)")*('전체 방제 정보'!$F$2:$F$3000=2)*(ROW('전체 방제 정보'!$E$2:$E$3000)-1))))) | H7: =IF(SUMPRODUCT(('전체 방제 정보'!$E$2:$E$3000=$B$4)*('전체 방제 정보'!$B$2:$B$3000="추천 약제(로테이션)")*('전체 방제 정보'!$F$2:$F$3000=2)*(ROW('전체 방제 정보'!$E$2:$E$3000)-1))=0,"",IF(INDEX('전체 방제 정보'!$J$2:$J$3000,SUMPRODUCT(('전체 방제 정보'!$E$2:$E$3000=$B$4)*('전체 방제 정보'!$B$2:$B$3000="추천 약제(로테이션)")*('전체 방제 정보'!$F$2:$F$3000=2)*(ROW('전체 방제 정보'!$E$2:$E$3000)-1)))="","",INDEX('전체 방제 정보'!$J$2:$J$3000,SUMPRODUCT(('전체 방제 정보'!$E$2:$E$3000=$B$4)*('전체 방제 정보'!$B$2:$B$3000="추천 약제(로테이션)")*('전체 방제 정보'!$F$2:$F$3000=2)*(ROW('전체 방제 정보'!$E$2:$E$3000)-1))))) | I7: =IF(SUMPRODUCT(('전체 방제 정보'!$E$2:$E$3000=$B$4)*('전체 방제 정보'!$B$2:$B$3000="추천 약제(로테이션)")*('전체 방제 정보'!$F$2:$F$3000=2)*(ROW('전체 방제 정보'!$E$2:$E$3000)-1))=0,"",IF(INDEX('전체 방제 정보'!$K$2:$K$3000,SUMPRODUCT(('전체 방제 정보'!$E$2:$E$3000=$B$4)*('전체 방제 정보'!$B$2:$B$3000="추천 약제(로테이션)")*('전체 방제 정보'!$F$2:$F$3000=2)*(ROW('전체 방제 정보'!$E$2:$E$3000)-1)))="","",INDEX('전체 방제 정보'!$K$2:$K$3000,SUMPRODUCT(('전체 방제 정보'!$E$2:$E$3000=$B$4)*('전체 방제 정보'!$B$2:$B$3000="추천 약제(로테이션)")*('전체 방제 정보'!$F$2:$F$3000=2)*(ROW('전체 방제 정보'!$E$2:$E$3000)-1))))) | J7: =IF(SUMPRODUCT(('전체 방제 정보'!$E$2:$E$3000=$B$4)*('전체 방제 정보'!$B$2:$B$3000="추천 약제(로테이션)")*('전체 방제 정보'!$F$2:$F$3000=2)*(ROW('전체 방제 정보'!$E$2:$E$3000)-1))=0,"",IF(INDEX('전체 방제 정보'!$L$2:$L$3000,SUMPRODUCT(('전체 방제 정보'!$E$2:$E$3000=$B$4)*('전체 방제 정보'!$B$2:$B$3000="추천 약제(로테이션)")*('전체 방제 정보'!$F$2:$F$3000=2)*(ROW('전체 방제 정보'!$E$2:$E$3000)-1)))="","",INDEX('전체 방제 정보'!$L$2:$L$3000,SUMPRODUCT(('전체 방제 정보'!$E$2:$E$3000=$B$4)*('전체 방제 정보'!$B$2:$B$3000="추천 약제(로테이션)")*('전체 방제 정보'!$F$2:$F$3000=2)*(ROW('전체 방제 정보'!$E$2:$E$3000)-1))))) | K7: =IF(SUMPRODUCT(('전체 방제 정보'!$E$2:$E$3000=$B$4)*('전체 방제 정보'!$B$2:$B$3000="추천 약제(로테이션)")*('전체 방제 정보'!$F$2:$F$3000=2)*(ROW('전체 방제 정보'!$E$2:$E$3000)-1))=0,"",IF(INDEX('전체 방제 정보'!$M$2:$M$3000,SUMPRODUCT(('전체 방제 정보'!$E$2:$E$3000=$B$4)*('전체 방제 정보'!$B$2:$B$3000="추천 약제(로테이션)")*('전체 방제 정보'!$F$2:$F$3000=2)*(ROW('전체 방제 정보'!$E$2:$E$3000)-1)))="","",INDEX('전체 방제 정보'!$M$2:$M$3000,SUMPRODUCT(('전체 방제 정보'!$E$2:$E$3000=$B$4)*('전체 방제 정보'!$B$2:$B$3000="추천 약제(로테이션)")*('전체 방제 정보'!$F$2:$F$3000=2)*(ROW('전체 방제 정보'!$E$2:$E$3000)-1))))) | L7: =IF(SUMPRODUCT(('전체 방제 정보'!$E$2:$E$3000=$B$4)*('전체 방제 정보'!$B$2:$B$3000="추천 약제(로테이션)")*('전체 방제 정보'!$F$2:$F$3000=2)*(ROW('전체 방제 정보'!$E$2:$E$3000)-1))=0,"",IF(INDEX('전체 방제 정보'!$N$2:$N$3000,SUMPRODUCT(('전체 방제 정보'!$E$2:$E$3000=$B$4)*('전체 방제 정보'!$B$2:$B$3000="추천 약제(로테이션)")*('전체 방제 정보'!$F$2:$F$3000=2)*(ROW('전체 방제 정보'!$E$2:$E$3000)-1)))="","",INDEX('전체 방제 정보'!$N$2:$N$3000,SUMPRODUCT(('전체 방제 정보'!$E$2:$E$3000=$B$4)*('전체 방제 정보'!$B$2:$B$3000="추천 약제(로테이션)")*('전체 방제 정보'!$F$2:$F$3000=2)*(ROW('전체 방제 정보'!$E$2:$E$3000)-1))))) | M7: =IF(SUMPRODUCT(('전체 방제 정보'!$E$2:$E$3000=$B$4)*('전체 방제 정보'!$B$2:$B$3000="추천 약제(로테이션)")*('전체 방제 정보'!$F$2:$F$3000=2)*(ROW('전체 방제 정보'!$E$2:$E$3000)-1))=0,"",IF(INDEX('전체 방제 정보'!$O$2:$O$3000,SUMPRODUCT(('전체 방제 정보'!$E$2:$E$3000=$B$4)*('전체 방제 정보'!$B$2:$B$3000="추천 약제(로테이션)")*('전체 방제 정보'!$F$2:$F$3000=2)*(ROW('전체 방제 정보'!$E$2:$E$3000)-1)))="","",INDEX('전체 방제 정보'!$O$2:$O$3000,SUMPRODUCT(('전체 방제 정보'!$E$2:$E$3000=$B$4)*('전체 방제 정보'!$B$2:$B$3000="추천 약제(로테이션)")*('전체 방제 정보'!$F$2:$F$3000=2)*(ROW('전체 방제 정보'!$E$2:$E$3000)-1))))) | N7: =IF(SUMPRODUCT(('전체 방제 정보'!$E$2:$E$3000=$B$4)*('전체 방제 정보'!$B$2:$B$3000="추천 약제(로테이션)")*('전체 방제 정보'!$F$2:$F$3000=2)*(ROW('전체 방제 정보'!$E$2:$E$3000)-1))=0,"",IF(INDEX('전체 방제 정보'!$P$2:$P$3000,SUMPRODUCT(('전체 방제 정보'!$E$2:$E$3000=$B$4)*('전체 방제 정보'!$B$2:$B$3000="추천 약제(로테이션)")*('전체 방제 정보'!$F$2:$F$3000=2)*(ROW('전체 방제 정보'!$E$2:$E$3000)-1)))="","",INDEX('전체 방제 정보'!$P$2:$P$3000,SUMPRODUCT(('전체 방제 정보'!$E$2:$E$3000=$B$4)*('전체 방제 정보'!$B$2:$B$3000="추천 약제(로테이션)")*('전체 방제 정보'!$F$2:$F$3000=2)*(ROW('전체 방제 정보'!$E$2:$E$3000)-1))))) | O7: =IF(SUMPRODUCT(('전체 방제 정보'!$E$2:$E$3000=$B$4)*('전체 방제 정보'!$B$2:$B$3000="추천 약제(로테이션)")*('전체 방제 정보'!$F$2:$F$3000=2)*(ROW('전체 방제 정보'!$E$2:$E$3000)-1))=0,"",IF(INDEX('전체 방제 정보'!$Q$2:$Q$3000,SUMPRODUCT(('전체 방제 정보'!$E$2:$E$3000=$B$4)*('전체 방제 정보'!$B$2:$B$3000="추천 약제(로테이션)")*('전체 방제 정보'!$F$2:$F$3000=2)*(ROW('전체 방제 정보'!$E$2:$E$3000)-1)))="","",INDEX('전체 방제 정보'!$Q$2:$Q$3000,SUMPRODUCT(('전체 방제 정보'!$E$2:$E$3000=$B$4)*('전체 방제 정보'!$B$2:$B$3000="추천 약제(로테이션)")*('전체 방제 정보'!$F$2:$F$3000=2)*(ROW('전체 방제 정보'!$E$2:$E$3000)-1))))) | P7: =IF(SUMPRODUCT(('전체 방제 정보'!$E$2:$E$3000=$B$4)*('전체 방제 정보'!$B$2:$B$3000="추천 약제(로테이션)")*('전체 방제 정보'!$F$2:$F$3000=2)*(ROW('전체 방제 정보'!$E$2:$E$3000)-1))=0,"",IF(INDEX('전체 방제 정보'!$R$2:$R$3000,SUMPRODUCT(('전체 방제 정보'!$E$2:$E$3000=$B$4)*('전체 방제 정보'!$B$2:$B$3000="추천 약제(로테이션)")*('전체 방제 정보'!$F$2:$F$3000=2)*(ROW('전체 방제 정보'!$E$2:$E$3000)-1)))="","",INDEX('전체 방제 정보'!$R$2:$R$3000,SUMPRODUCT(('전체 방제 정보'!$E$2:$E$3000=$B$4)*('전체 방제 정보'!$B$2:$B$3000="추천 약제(로테이션)")*('전체 방제 정보'!$F$2:$F$3000=2)*(ROW('전체 방제 정보'!$E$2:$E$3000)-1)))))
D8: =IF(SUMPRODUCT(('전체 방제 정보'!$E$2:$E$3000=$B$4)*('전체 방제 정보'!$B$2:$B$3000="추천 약제(로테이션)")*('전체 방제 정보'!$F$2:$F$3000=3)*(ROW('전체 방제 정보'!$E$2:$E$3000)-1))=0,"",3) | E8: =IF(SUMPRODUCT(('전체 방제 정보'!$E$2:$E$3000=$B$4)*('전체 방제 정보'!$B$2:$B$3000="추천 약제(로테이션)")*('전체 방제 정보'!$F$2:$F$3000=3)*(ROW('전체 방제 정보'!$E$2:$E$3000)-1))=0,"",IF(INDEX('전체 방제 정보'!$G$2:$G$3000,SUMPRODUCT(('전체 방제 정보'!$E$2:$E$3000=$B$4)*('전체 방제 정보'!$B$2:$B$3000="추천 약제(로테이션)")*('전체 방제 정보'!$F$2:$F$3000=3)*(ROW('전체 방제 정보'!$E$2:$E$3000)-1)))="","",INDEX('전체 방제 정보'!$G$2:$G$3000,SUMPRODUCT(('전체 방제 정보'!$E$2:$E$3000=$B$4)*('전체 방제 정보'!$B$2:$B$3000="추천 약제(로테이션)")*('전체 방제 정보'!$F$2:$F$3000=3)*(ROW('전체 방제 정보'!$E$2:$E$3000)-1))))) | F8: =IF(SUMPRODUCT(('전체 방제 정보'!$E$2:$E$3000=$B$4)*('전체 방제 정보'!$B$2:$B$3000="추천 약제(로테이션)")*('전체 방제 정보'!$F$2:$F$3000=3)*(ROW('전체 방제 정보'!$E$2:$E$3000)-1))=0,"",IF(INDEX('전체 방제 정보'!$H$2:$H$3000,SUMPRODUCT(('전체 방제 정보'!$E$2:$E$3000=$B$4)*('전체 방제 정보'!$B$2:$B$3000="추천 약제(로테이션)")*('전체 방제 정보'!$F$2:$F$3000=3)*(ROW('전체 방제 정보'!$E$2:$E$3000)-1)))="","",INDEX('전체 방제 정보'!$H$2:$H$3000,SUMPRODUCT(('전체 방제 정보'!$E$2:$E$3000=$B$4)*('전체 방제 정보'!$B$2:$B$3000="추천 약제(로테이션)")*('전체 방제 정보'!$F$2:$F$3000=3)*(ROW('전체 방제 정보'!$E$2:$E$3000)-1))))) | G8: =IF(SUMPRODUCT(('전체 방제 정보'!$E$2:$E$3000=$B$4)*('전체 방제 정보'!$B$2:$B$3000="추천 약제(로테이션)")*('전체 방제 정보'!$F$2:$F$3000=3)*(ROW('전체 방제 정보'!$E$2:$E$3000)-1))=0,"",IF(INDEX('전체 방제 정보'!$I$2:$I$3000,SUMPRODUCT(('전체 방제 정보'!$E$2:$E$3000=$B$4)*('전체 방제 정보'!$B$2:$B$3000="추천 약제(로테이션)")*('전체 방제 정보'!$F$2:$F$3000=3)*(ROW('전체 방제 정보'!$E$2:$E$3000)-1)))="","",INDEX('전체 방제 정보'!$I$2:$I$3000,SUMPRODUCT(('전체 방제 정보'!$E$2:$E$3000=$B$4)*('전체 방제 정보'!$B$2:$B$3000="추천 약제(로테이션)")*('전체 방제 정보'!$F$2:$F$3000=3)*(ROW('전체 방제 정보'!$E$2:$E$3000)-1))))) | H8: =IF(SUMPRODUCT(('전체 방제 정보'!$E$2:$E$3000=$B$4)*('전체 방제 정보'!$B$2:$B$3000="추천 약제(로테이션)")*('전체 방제 정보'!$F$2:$F$3000=3)*(ROW('전체 방제 정보'!$E$2:$E$3000)-1))=0,"",IF(INDEX('전체 방제 정보'!$J$2:$J$3000,SUMPRODUCT(('전체 방제 정보'!$E$2:$E$3000=$B$4)*('전체 방제 정보'!$B$2:$B$3000="추천 약제(로테이션)")*('전체 방제 정보'!$F$2:$F$3000=3)*(ROW('전체 방제 정보'!$E$2:$E$3000)-1)))="","",INDEX('전체 방제 정보'!$J$2:$J$3000,SUMPRODUCT(('전체 방제 정보'!$E$2:$E$3000=$B$4)*('전체 방제 정보'!$B$2:$B$3000="추천 약제(로테이션)")*('전체 방제 정보'!$F$2:$F$3000=3)*(ROW('전체 방제 정보'!$E$2:$E$3000)-1))))) | I8: =IF(SUMPRODUCT(('전체 방제 정보'!$E$2:$E$3000=$B$4)*('전체 방제 정보'!$B$2:$B$3000="추천 약제(로테이션)")*('전체 방제 정보'!$F$2:$F$3000=3)*(ROW('전체 방제 정보'!$E$2:$E$3000)-1))=0,"",IF(INDEX('전체 방제 정보'!$K$2:$K$3000,SUMPRODUCT(('전체 방제 정보'!$E$2:$E$3000=$B$4)*('전체 방제 정보'!$B$2:$B$3000="추천 약제(로테이션)")*('전체 방제 정보'!$F$2:$F$3000=3)*(ROW('전체 방제 정보'!$E$2:$E$3000)-1)))="","",INDEX('전체 방제 정보'!$K$2:$K$3000,SUMPRODUCT(('전체 방제 정보'!$E$2:$E$3000=$B$4)*('전체 방제 정보'!$B$2:$B$3000="추천 약제(로테이션)")*('전체 방제 정보'!$F$2:$F$3000=3)*(ROW('전체 방제 정보'!$E$2:$E$3000)-1))))) | J8: =IF(SUMPRODUCT(('전체 방제 정보'!$E$2:$E$3000=$B$4)*('전체 방제 정보'!$B$2:$B$3000="추천 약제(로테이션)")*('전체 방제 정보'!$F$2:$F$3000=3)*(ROW('전체 방제 정보'!$E$2:$E$3000)-1))=0,"",IF(INDEX('전체 방제 정보'!$L$2:$L$3000,SUMPRODUCT(('전체 방제 정보'!$E$2:$E$3000=$B$4)*('전체 방제 정보'!$B$2:$B$3000="추천 약제(로테이션)")*('전체 방제 정보'!$F$2:$F$3000=3)*(ROW('전체 방제 정보'!$E$2:$E$3000)-1)))="","",INDEX('전체 방제 정보'!$L$2:$L$3000,SUMPRODUCT(('전체 방제 정보'!$E$2:$E$3000=$B$4)*('전체 방제 정보'!$B$2:$B$3000="추천 약제(로테이션)")*('전체 방제 정보'!$F$2:$F$3000=3)*(ROW('전체 방제 정보'!$E$2:$E$3000)-1))))) | K8: =IF(SUMPRODUCT(('전체 방제 정보'!$E$2:$E$3000=$B$4)*('전체 방제 정보'!$B$2:$B$3000="추천 약제(로테이션)")*('전체 방제 정보'!$F$2:$F$3000=3)*(ROW('전체 방제 정보'!$E$2:$E$3000)-1))=0,"",IF(INDEX('전체 방제 정보'!$M$2:$M$3000,SUMPRODUCT(('전체 방제 정보'!$E$2:$E$3000=$B$4)*('전체 방제 정보'!$B$2:$B$3000="추천 약제(로테이션)")*('전체 방제 정보'!$F$2:$F$3000=3)*(ROW('전체 방제 정보'!$E$2:$E$3000)-1)))="","",INDEX('전체 방제 정보'!$M$2:$M$3000,SUMPRODUCT(('전체 방제 정보'!$E$2:$E$3000=$B$4)*('전체 방제 정보'!$B$2:$B$3000="추천 약제(로테이션)")*('전체 방제 정보'!$F$2:$F$3000=3)*(ROW('전체 방제 정보'!$E$2:$E$3000)-1))))) | L8: =IF(SUMPRODUCT(('전체 방제 정보'!$E$2:$E$3000=$B$4)*('전체 방제 정보'!$B$2:$B$3000="추천 약제(로테이션)")*('전체 방제 정보'!$F$2:$F$3000=3)*(ROW('전체 방제 정보'!$E$2:$E$3000)-1))=0,"",IF(INDEX('전체 방제 정보'!$N$2:$N$3000,SUMPRODUCT(('전체 방제 정보'!$E$2:$E$3000=$B$4)*('전체 방제 정보'!$B$2:$B$3000="추천 약제(로테이션)")*('전체 방제 정보'!$F$2:$F$3000=3)*(ROW('전체 방제 정보'!$E$2:$E$3000)-1)))="","",INDEX('전체 방제 정보'!$N$2:$N$3000,SUMPRODUCT(('전체 방제 정보'!$E$2:$E$3000=$B$4)*('전체 방제 정보'!$B$2:$B$3000="추천 약제(로테이션)")*('전체 방제 정보'!$F$2:$F$3000=3)*(ROW('전체 방제 정보'!$E$2:$E$3000)-1))))) | M8: =IF(SUMPRODUCT(('전체 방제 정보'!$E$2:$E$3000=$B$4)*('전체 방제 정보'!$B$2:$B$3000="추천 약제(로테이션)")*('전체 방제 정보'!$F$2:$F$3000=3)*(ROW('전체 방제 정보'!$E$2:$E$3000)-1))=0,"",IF(INDEX('전체 방제 정보'!$O$2:$O$3000,SUMPRODUCT(('전체 방제 정보'!$E$2:$E$3000=$B$4)*('전체 방제 정보'!$B$2:$B$3000="추천 약제(로테이션)")*('전체 방제 정보'!$F$2:$F$3000=3)*(ROW('전체 방제 정보'!$E$2:$E$3000)-1)))="","",INDEX('전체 방제 정보'!$O$2:$O$3000,SUMPRODUCT(('전체 방제 정보'!$E$2:$E$3000=$B$4)*('전체 방제 정보'!$B$2:$B$3000="추천 약제(로테이션)")*('전체 방제 정보'!$F$2:$F$3000=3)*(ROW('전체 방제 정보'!$E$2:$E$3000)-1))))) | N8: =IF(SUMPRODUCT(('전체 방제 정보'!$E$2:$E$3000=$B$4)*('전체 방제 정보'!$B$2:$B$3000="추천 약제(로테이션)")*('전체 방제 정보'!$F$2:$F$3000=3)*(ROW('전체 방제 정보'!$E$2:$E$3000)-1))=0,"",IF(INDEX('전체 방제 정보'!$P$2:$P$3000,SUMPRODUCT(('전체 방제 정보'!$E$2:$E$3000=$B$4)*('전체 방제 정보'!$B$2:$B$3000="추천 약제(로테이션)")*('전체 방제 정보'!$F$2:$F$3000=3)*(ROW('전체 방제 정보'!$E$2:$E$3000)-1)))="","",INDEX('전체 방제 정보'!$P$2:$P$3000,SUMPRODUCT(('전체 방제 정보'!$E$2:$E$3000=$B$4)*('전체 방제 정보'!$B$2:$B$3000="추천 약제(로테이션)")*('전체 방제 정보'!$F$2:$F$3000=3)*(ROW('전체 방제 정보'!$E$2:$E$3000)-1))))) | O8: =IF(SUMPRODUCT(('전체 방제 정보'!$E$2:$E$3000=$B$4)*('전체 방제 정보'!$B$2:$B$3000="추천 약제(로테이션)")*('전체 방제 정보'!$F$2:$F$3000=3)*(ROW('전체 방제 정보'!$E$2:$E$3000)-1))=0,"",IF(INDEX('전체 방제 정보'!$Q$2:$Q$3000,SUMPRODUCT(('전체 방제 정보'!$E$2:$E$3000=$B$4)*('전체 방제 정보'!$B$2:$B$3000="추천 약제(로테이션)")*('전체 방제 정보'!$F$2:$F$3000=3)*(ROW('전체 방제 정보'!$E$2:$E$3000)-1)))="","",INDEX('전체 방제 정보'!$Q$2:$Q$3000,SUMPRODUCT(('전체 방제 정보'!$E$2:$E$3000=$B$4)*('전체 방제 정보'!$B$2:$B$3000="추천 약제(로테이션)")*('전체 방제 정보'!$F$2:$F$3000=3)*(ROW('전체 방제 정보'!$E$2:$E$3000)-1))))) | P8: =IF(SUMPRODUCT(('전체 방제 정보'!$E$2:$E$3000=$B$4)*('전체 방제 정보'!$B$2:$B$3000="추천 약제(로테이션)")*('전체 방제 정보'!$F$2:$F$3000=3)*(ROW('전체 방제 정보'!$E$2:$E$3000)-1))=0,"",IF(INDEX('전체 방제 정보'!$R$2:$R$3000,SUMPRODUCT(('전체 방제 정보'!$E$2:$E$3000=$B$4)*('전체 방제 정보'!$B$2:$B$3000="추천 약제(로테이션)")*('전체 방제 정보'!$F$2:$F$3000=3)*(ROW('전체 방제 정보'!$E$2:$E$3000)-1)))="","",INDEX('전체 방제 정보'!$R$2:$R$3000,SUMPRODUCT(('전체 방제 정보'!$E$2:$E$3000=$B$4)*('전체 방제 정보'!$B$2:$B$3000="추천 약제(로테이션)")*('전체 방제 정보'!$F$2:$F$3000=3)*(ROW('전체 방제 정보'!$E$2:$E$3000)-1)))))
D9: =IF(SUMPRODUCT(('전체 방제 정보'!$E$2:$E$3000=$B$4)*('전체 방제 정보'!$B$2:$B$3000="추천 약제(로테이션)")*('전체 방제 정보'!$F$2:$F$3000=4)*(ROW('전체 방제 정보'!$E$2:$E$3000)-1))=0,"",4) | E9: =IF(SUMPRODUCT(('전체 방제 정보'!$E$2:$E$3000=$B$4)*('전체 방제 정보'!$B$2:$B$3000="추천 약제(로테이션)")*('전체 방제 정보'!$F$2:$F$3000=4)*(ROW('전체 방제 정보'!$E$2:$E$3000)-1))=0,"",IF(INDEX('전체 방제 정보'!$G$2:$G$3000,SUMPRODUCT(('전체 방제 정보'!$E$2:$E$3000=$B$4)*('전체 방제 정보'!$B$2:$B$3000="추천 약제(로테이션)")*('전체 방제 정보'!$F$2:$F$3000=4)*(ROW('전체 방제 정보'!$E$2:$E$3000)-1)))="","",INDEX('전체 방제 정보'!$G$2:$G$3000,SUMPRODUCT(('전체 방제 정보'!$E$2:$E$3000=$B$4)*('전체 방제 정보'!$B$2:$B$3000="추천 약제(로테이션)")*('전체 방제 정보'!$F$2:$F$3000=4)*(ROW('전체 방제 정보'!$E$2:$E$3000)-1))))) | F9: =IF(SUMPRODUCT(('전체 방제 정보'!$E$2:$E$3000=$B$4)*('전체 방제 정보'!$B$2:$B$3000="추천 약제(로테이션)")*('전체 방제 정보'!$F$2:$F$3000=4)*(ROW('전체 방제 정보'!$E$2:$E$3000)-1))=0,"",IF(INDEX('전체 방제 정보'!$H$2:$H$3000,SUMPRODUCT(('전체 방제 정보'!$E$2:$E$3000=$B$4)*('전체 방제 정보'!$B$2:$B$3000="추천 약제(로테이션)")*('전체 방제 정보'!$F$2:$F$3000=4)*(ROW('전체 방제 정보'!$E$2:$E$3000)-1)))="","",INDEX('전체 방제 정보'!$H$2:$H$3000,SUMPRODUCT(('전체 방제 정보'!$E$2:$E$3000=$B$4)*('전체 방제 정보'!$B$2:$B$3000="추천 약제(로테이션)")*('전체 방제 정보'!$F$2:$F$3000=4)*(ROW('전체 방제 정보'!$E$2:$E$3000)-1))))) | G9: =IF(SUMPRODUCT(('전체 방제 정보'!$E$2:$E$3000=$B$4)*('전체 방제 정보'!$B$2:$B$3000="추천 약제(로테이션)")*('전체 방제 정보'!$F$2:$F$3000=4)*(ROW('전체 방제 정보'!$E$2:$E$3000)-1))=0,"",IF(INDEX('전체 방제 정보'!$I$2:$I$3000,SUMPRODUCT(('전체 방제 정보'!$E$2:$E$3000=$B$4)*('전체 방제 정보'!$B$2:$B$3000="추천 약제(로테이션)")*('전체 방제 정보'!$F$2:$F$3000=4)*(ROW('전체 방제 정보'!$E$2:$E$3000)-1)))="","",INDEX('전체 방제 정보'!$I$2:$I$3000,SUMPRODUCT(('전체 방제 정보'!$E$2:$E$3000=$B$4)*('전체 방제 정보'!$B$2:$B$3000="추천 약제(로테이션)")*('전체 방제 정보'!$F$2:$F$3000=4)*(ROW('전체 방제 정보'!$E$2:$E$3000)-1))))) | H9: =IF(SUMPRODUCT(('전체 방제 정보'!$E$2:$E$3000=$B$4)*('전체 방제 정보'!$B$2:$B$3000="추천 약제(로테이션)")*('전체 방제 정보'!$F$2:$F$3000=4)*(ROW('전체 방제 정보'!$E$2:$E$3000)-1))=0,"",IF(INDEX('전체 방제 정보'!$J$2:$J$3000,SUMPRODUCT(('전체 방제 정보'!$E$2:$E$3000=$B$4)*('전체 방제 정보'!$B$2:$B$3000="추천 약제(로테이션)")*('전체 방제 정보'!$F$2:$F$3000=4)*(ROW('전체 방제 정보'!$E$2:$E$3000)-1)))="","",INDEX('전체 방제 정보'!$J$2:$J$3000,SUMPRODUCT(('전체 방제 정보'!$E$2:$E$3000=$B$4)*('전체 방제 정보'!$B$2:$B$3000="추천 약제(로테이션)")*('전체 방제 정보'!$F$2:$F$3000=4)*(ROW('전체 방제 정보'!$E$2:$E$3000)-1))))) | I9: =IF(SUMPRODUCT(('전체 방제 정보'!$E$2:$E$3000=$B$4)*('전체 방제 정보'!$B$2:$B$3000="추천 약제(로테이션)")*('전체 방제 정보'!$F$2:$F$3000=4)*(ROW('전체 방제 정보'!$E$2:$E$3000)-1))=0,"",IF(INDEX('전체 방제 정보'!$K$2:$K$3000,SUMPRODUCT(('전체 방제 정보'!$E$2:$E$3000=$B$4)*('전체 방제 정보'!$B$2:$B$3000="추천 약제(로테이션)")*('전체 방제 정보'!$F$2:$F$3000=4)*(ROW('전체 방제 정보'!$E$2:$E$3000)-1)))="","",INDEX('전체 방제 정보'!$K$2:$K$3000,SUMPRODUCT(('전체 방제 정보'!$E$2:$E$3000=$B$4)*('전체 방제 정보'!$B$2:$B$3000="추천 약제(로테이션)")*('전체 방제 정보'!$F$2:$F$3000=4)*(ROW('전체 방제 정보'!$E$2:$E$3000)-1))))) | J9: =IF(SUMPRODUCT(('전체 방제 정보'!$E$2:$E$3000=$B$4)*('전체 방제 정보'!$B$2:$B$3000="추천 약제(로테이션)")*('전체 방제 정보'!$F$2:$F$3000=4)*(ROW('전체 방제 정보'!$E$2:$E$3000)-1))=0,"",IF(INDEX('전체 방제 정보'!$L$2:$L$3000,SUMPRODUCT(('전체 방제 정보'!$E$2:$E$3000=$B$4)*('전체 방제 정보'!$B$2:$B$3000="추천 약제(로테이션)")*('전체 방제 정보'!$F$2:$F$3000=4)*(ROW('전체 방제 정보'!$E$2:$E$3000)-1)))="","",INDEX('전체 방제 정보'!$L$2:$L$3000,SUMPRODUCT(('전체 방제 정보'!$E$2:$E$3000=$B$4)*('전체 방제 정보'!$B$2:$B$3000="추천 약제(로테이션)")*('전체 방제 정보'!$F$2:$F$3000=4)*(ROW('전체 방제 정보'!$E$2:$E$3000)-1))))) | K9: =IF(SUMPRODUCT(('전체 방제 정보'!$E$2:$E$3000=$B$4)*('전체 방제 정보'!$B$2:$B$3000="추천 약제(로테이션)")*('전체 방제 정보'!$F$2:$F$3000=4)*(ROW('전체 방제 정보'!$E$2:$E$3000)-1))=0,"",IF(INDEX('전체 방제 정보'!$M$2:$M$3000,SUMPRODUCT(('전체 방제 정보'!$E$2:$E$3000=$B$4)*('전체 방제 정보'!$B$2:$B$3000="추천 약제(로테이션)")*('전체 방제 정보'!$F$2:$F$3000=4)*(ROW('전체 방제 정보'!$E$2:$E$3000)-1)))="","",INDEX('전체 방제 정보'!$M$2:$M$3000,SUMPRODUCT(('전체 방제 정보'!$E$2:$E$3000=$B$4)*('전체 방제 정보'!$B$2:$B$3000="추천 약제(로테이션)")*('전체 방제 정보'!$F$2:$F$3000=4)*(ROW('전체 방제 정보'!$E$2:$E$3000)-1))))) | L9: =IF(SUMPRODUCT(('전체 방제 정보'!$E$2:$E$3000=$B$4)*('전체 방제 정보'!$B$2:$B$3000="추천 약제(로테이션)")*('전체 방제 정보'!$F$2:$F$3000=4)*(ROW('전체 방제 정보'!$E$2:$E$3000)-1))=0,"",IF(INDEX('전체 방제 정보'!$N$2:$N$3000,SUMPRODUCT(('전체 방제 정보'!$E$2:$E$3000=$B$4)*('전체 방제 정보'!$B$2:$B$3000="추천 약제(로테이션)")*('전체 방제 정보'!$F$2:$F$3000=4)*(ROW('전체 방제 정보'!$E$2:$E$3000)-1)))="","",INDEX('전체 방제 정보'!$N$2:$N$3000,SUMPRODUCT(('전체 방제 정보'!$E$2:$E$3000=$B$4)*('전체 방제 정보'!$B$2:$B$3000="추천 약제(로테이션)")*('전체 방제 정보'!$F$2:$F$3000=4)*(ROW('전체 방제 정보'!$E$2:$E$3000)-1))))) | M9: =IF(SUMPRODUCT(('전체 방제 정보'!$E$2:$E$3000=$B$4)*('전체 방제 정보'!$B$2:$B$3000="추천 약제(로테이션)")*('전체 방제 정보'!$F$2:$F$3000=4)*(ROW('전체 방제 정보'!$E$2:$E$3000)-1))=0,"",IF(INDEX('전체 방제 정보'!$O$2:$O$3000,SUMPRODUCT(('전체 방제 정보'!$E$2:$E$3000=$B$4)*('전체 방제 정보'!$B$2:$B$3000="추천 약제(로테이션)")*('전체 방제 정보'!$F$2:$F$3000=4)*(ROW('전체 방제 정보'!$E$2:$E$3000)-1)))="","",INDEX('전체 방제 정보'!$O$2:$O$3000,SUMPRODUCT(('전체 방제 정보'!$E$2:$E$3000=$B$4)*('전체 방제 정보'!$B$2:$B$3000="추천 약제(로테이션)")*('전체 방제 정보'!$F$2:$F$3000=4)*(ROW('전체 방제 정보'!$E$2:$E$3000)-1))))) | N9: =IF(SUMPRODUCT(('전체 방제 정보'!$E$2:$E$3000=$B$4)*('전체 방제 정보'!$B$2:$B$3000="추천 약제(로테이션)")*('전체 방제 정보'!$F$2:$F$3000=4)*(ROW('전체 방제 정보'!$E$2:$E$3000)-1))=0,"",IF(INDEX('전체 방제 정보'!$P$2:$P$3000,SUMPRODUCT(('전체 방제 정보'!$E$2:$E$3000=$B$4)*('전체 방제 정보'!$B$2:$B$3000="추천 약제(로테이션)")*('전체 방제 정보'!$F$2:$F$3000=4)*(ROW('전체 방제 정보'!$E$2:$E$3000)-1)))="","",INDEX('전체 방제 정보'!$P$2:$P$3000,SUMPRODUCT(('전체 방제 정보'!$E$2:$E$3000=$B$4)*('전체 방제 정보'!$B$2:$B$3000="추천 약제(로테이션)")*('전체 방제 정보'!$F$2:$F$3000=4)*(ROW('전체 방제 정보'!$E$2:$E$3000)-1))))) | O9: =IF(SUMPRODUCT(('전체 방제 정보'!$E$2:$E$3000=$B$4)*('전체 방제 정보'!$B$2:$B$3000="추천 약제(로테이션)")*('전체 방제 정보'!$F$2:$F$3000=4)*(ROW('전체 방제 정보'!$E$2:$E$3000)-1))=0,"",IF(INDEX('전체 방제 정보'!$Q$2:$Q$3000,SUMPRODUCT(('전체 방제 정보'!$E$2:$E$3000=$B$4)*('전체 방제 정보'!$B$2:$B$3000="추천 약제(로테이션)")*('전체 방제 정보'!$F$2:$F$3000=4)*(ROW('전체 방제 정보'!$E$2:$E$3000)-1)))="","",INDEX('전체 방제 정보'!$Q$2:$Q$3000,SUMPRODUCT(('전체 방제 정보'!$E$2:$E$3000=$B$4)*('전체 방제 정보'!$B$2:$B$3000="추천 약제(로테이션)")*('전체 방제 정보'!$F$2:$F$3000=4)*(ROW('전체 방제 정보'!$E$2:$E$3000)-1))))) | P9: =IF(SUMPRODUCT(('전체 방제 정보'!$E$2:$E$3000=$B$4)*('전체 방제 정보'!$B$2:$B$3000="추천 약제(로테이션)")*('전체 방제 정보'!$F$2:$F$3000=4)*(ROW('전체 방제 정보'!$E$2:$E$3000)-1))=0,"",IF(INDEX('전체 방제 정보'!$R$2:$R$3000,SUMPRODUCT(('전체 방제 정보'!$E$2:$E$3000=$B$4)*('전체 방제 정보'!$B$2:$B$3000="추천 약제(로테이션)")*('전체 방제 정보'!$F$2:$F$3000=4)*(ROW('전체 방제 정보'!$E$2:$E$3000)-1)))="","",INDEX('전체 방제 정보'!$R$2:$R$3000,SUMPRODUCT(('전체 방제 정보'!$E$2:$E$3000=$B$4)*('전체 방제 정보'!$B$2:$B$3000="추천 약제(로테이션)")*('전체 방제 정보'!$F$2:$F$3000=4)*(ROW('전체 방제 정보'!$E$2:$E$3000)-1)))))
A11: ② 병해충 | D11: 적용 약제 | I11: 사용 방법 (희석 · 방법 · 시기 · 횟수) | O11: 주의사항 | Q11: 약제 상세
A12: 병해충명 | B12: 병해충 구분 | C12: 작물명 | D12: 순위 | E12: 약제명 | F12: 제형 | G12: 학교 보유 | H12: 방제 구분 | I12: 희석배수 | J12: 살포 방법 | K12: 살포 시기 | L12: 수확 전 사용 제한 | M12: 최대 살포 횟수 | N12: 살포 간격 | O12: 주의사항 | P12: 혼용 정보 | Q12: 유효성분 | R12: 작용기작
A13: 갈색무늬병 | B13: 병해 | C13: 파프리카 | D13: 1 | E13: 탄쟈비상 | F13: 액상수화제 | G13: 미보유 | H13: 등록 농약 | I13: 2000 | J13: 경엽처리 | L13: 수확3일전 | M13: 3 | O13: 등록된 약제가 1개뿐이라 대체(로테이션)용은 없습니다. | P13: 모스피란과 혼용 가능(경농 조회) | Q13: Trifloxystrobin | R13: 다3
A14: 갈색점무늬병 | B14: 병해 | C14: 파프리카 | D14: 1 | E14: 버픽스 | F14: 액상수화제 | G14: 보유 | H14: 등록 농약 | I14: 2000 | J14: 경엽처리 | L14: 수확3일전 | M14: 3 | P14: 혼용정보 미확인 — 사용 전 제조사(동방아그로 1644-7337) 확인 | Q14: Florylpicoxamid | R14: 다4
A15: 갈색점무늬병 | B15: 병해 | C15: 파프리카 | D15: 2 | E15: 벨리스플러스 | F15: 입상수화제 | G15: 보유 | H15: 등록 농약 | I15: 2000 | J15: 경엽처리 | L15: 수확5일전 | M15: 2 | P15: 모스피란과 혼용 가능(경농 조회) | Q15: Boscalid+Pyraclostrobin | R15: 다3,다2
A16: 갈색점무늬병 | B16: 병해 | C16: 파프리카 | D16: 3 | E16: 오조아 | F16: 수화제 | G16: 미보유 | H16: 등록 농약 | I16: 2000 | J16: 경엽처리 | L16: 수확5일전 | M16: 4 | Q16: Fluazinam | R16: 다5
A17: 갈색점무늬병 | B17: 병해 | C17: 파프리카 | D17: 4 | E17: 경탄 | F17: 액상수화제 | G17: 미보유 | H17: 등록 농약 | I17: 1000 | J17: 경엽처리 | L17: 수확3일전 | M17: 3 | Q17: Chlorothalonil+Kresoxim-methyl | R17: 카,다3
A18: 붉은썩음병 | B18: 병해 | C18: 파프리카 | D18: 1 | E18: 스포르곤 | F18: 수화제 | G18: 미보유 | H18: 등록 농약 | I18: 1000 | J18: 관주처리 | L18: 수확7일전 | M18: 3 | P18: 모스피란 · 코니도 · 타스타와의 혼용 조합 자료 없음 | Q18: Prochloraz-manganese | R18: 사1
A19: 붉은썩음병 | B19: 병해 | C19: 파프리카 | D19: 2 | E19: 균디스 | F19: 액상수화제 | G19: 미보유 | H19: 등록 농약 | I19: 4000 | J19: 관주처리 | L19: 수확3일전 | M19: 3 | Q19: Azoxystrobin | R19: 다3
A20: 뿌리썩음병 | B20: 병해 | C20: 파프리카 | D20: 1 | E20: 스포르곤 | F20: 입제 | G20: 미보유 | H20: 등록 농약 | I20: 1000 | J20: 관주처리 | L20: 수확7일전 | M20: 3 | O20: 등록된 약제가 1개뿐이라 대체(로테이션)용은 없습니다. | P20: 모스피란 · 코니도 · 타스타와의 혼용 조합 자료 없음 | Q20: Prochloraz-manganese | R20: 사1
A21: 세균점무늬병 | B21: 병해 | C21: 파프리카 | D21: 1 | E21: 무름반점뚝 | F21: 수화제 | G21: 보유 | H21: 등록 농약 | I21: 1000 | J21: 경엽처리 | L21: 수확7일전 | M21: 3 | P21: 혼용정보 미확인 — 사용 전 제조사(대유) 확인 | Q21: Oxolinic acid | R21: 가4
A22: 세균점무늬병 | B22: 병해 | C22: 파프리카 | D22: 2 | E22: 미스타클린 | F22: 수화제 | G22: 보유 | H22: 등록 농약 | I22: 1000 | J22: 경엽처리 | L22: 수확3일전 | M22: 3 | Q22: Oxytetracycline dihydrate+Validamycin A | R22: 라5+미분류(살균제)
A23: 세균점무늬병 | B23: 병해 | C23: 파프리카 | D23: 3 | E23: 가스란 | F23: 수화제 | G23: 미보유 | H23: 등록 농약 | I23: 1000 | J23: 경엽처리 | L23: 수확2일전 | M23: 5 | P23: 모스피란과 혼용 가능(경농 조회) | Q23: 코퍼옥시클로라이드.가스가마이신 (Copper oxychloride+Kasugamycin) | R23: 라3,카
A24: 세균점무늬병 | B24: 병해 | C24: 파프리카 | D24: 4 | E24: 골든벨 | F24: 액상수화제 | G24: 미보유 | H24: 등록 농약 | I24: 1000 | J24: 경엽처리 | L24: 수확2일전 | M24: 3 | Q24: 가스가마이신.티오파네이트메틸 (Kasugamycin+Thiophanate-methyl) | R24: 나1,라3
A25: 잿빛곰팡이병 | B25: 병해 | C25: 파프리카 | D25: 1 | E25: 버픽스 | F25: 액상수화제 | G25: 보유 | H25: 등록 농약 | I25: 2000 | J25: 경엽처리 | L25: 수확3일전 | M25: 3 | P25: 혼용정보 미확인 — 사용 전 제조사(동방아그로 1644-7337) 확인 | Q25: Florylpicoxamid | R25: 다4
A26: 잿빛곰팡이병 | B26: 병해 | C26: 파프리카 | D26: 2 | E26: 미래빛 | F26: 액상수화제 | G26: 보유 | H26: 등록 농약 | I26: 4000 | J26: 경엽처리 | L26: 수확3일전 | M26: 3 | Q26: Pydiflumetofen | R26: 다2
A27: 잿빛곰팡이병 | B27: 병해 | C27: 파프리카 | D27: 3 | E27: 사파이어 | F27: 액상수화제 | G27: 보유 | H27: 등록 농약 | I27: 2000 | J27: 경엽처리 | L27: 수확3일전 | M27: 2 | Q27: Fludioxonil | R27: 마2
A28: 잿빛곰팡이병 | B28: 병해 | C28: 파프리카 | D28: 4 | E28: 오조아 | F28: 수화제 | G28: 미보유 | H28: 등록 농약 | I28: 2000 | J28: 경엽처리 | L28: 수확5일전 | M28: 4 | Q28: Fluazinam | R28: 다5
A29: 탄저병 | B29: 병해 | C29: 파프리카 | D29: 1 | E29: 벨리스플러스 | F29: 입상수화제 | G29: 보유 | H29: 등록 농약 | I29: 2000 | J29: 경엽처리 | L29: 수확5일전 | M29: 2 | P29: 모스피란과 혼용 가능(경농 조회) | Q29: Boscalid+Pyraclostrobin | R29: 다3,다2
A30: 탄저병 | B30: 병해 | C30: 파프리카 | D30: 2 | E30: 다놀라 | F30: 액상 | G30: 보유 | H30: 등록 농약 | O30: 원본에 희석배수·사용방법·안전사용기준 미기재 | P30: 모스피란과 혼용 가능(경농 조회) | Q30: 디페노코나졸.피라클로스트로빈 (Difenoconazole+Pyraclostrobin) | R30: 사1,다3
A31: 탄저병 | B31: 병해 | C31: 파프리카 | D31: 3 | E31: 미리본 | G31: 보유 | H31: 등록 농약 | O31: 원본에 희석배수·사용방법·안전사용기준 미기재 | Q31: 플룩사피록사드.피라클로스트로빈 (Fluxapyroxad+Pyraclostrobin) | R31: 다3,다2
A32: 탄저병 | B32: 병해 | C32: 파프리카 | D32: 4 | E32: 벨쿠트 | F32: 수화제 | G32: 보유 | H32: 등록 농약 | O32: 원본에 희석배수·사용방법·안전사용기준 미기재 | P32: 모스피란 · 코니도와 혼용 가능(경농·팜한농 조회) | Q32: 이미녹타딘트리스알베실레이트 (Iminoctadin tris (albesilate)) | R32: 카
A33: 풋마름병 | B33: 병해 | C33: 파프리카 | D33: 1 | E33: 크린쏘일 | F33: 입제 | G33: 미보유 | H33: 등록 농약 | J33: 토양처리 | K33: 정식 4주일 전 | M33: 1 | O33: 가이드 추천문에는 유효성분 'Metam-sodium', 사용방법 '관주처리', 안전사용기준 '정식4주전 / 1회'(으)로 표기 — 원본 내 표기 상이, 확인 필요 | Q33: Dazomet | R33: 미분류(살균제)
A34: 거세미나방류 | B34: 해충 | C34: 파프리카 | D34: 1 | E34: 쏘버린 | F34: 입제 | G34: 미보유 | H34: 등록 농약 | J34: 토양처리 | K34: 정식기 | M34: 1 | P34: 정식 시 흙에 뿌리는 입제 — 혼용정보표 대상 아님 | Q34: Carbosulfan | R34: 1a
A35: 거세미나방류 | B35: 해충 | C35: 파프리카 | D35: 2 | E35: 보라충 | F35: 입제 | G35: 미보유 | H35: 등록 농약 | J35: 토양처리 | K35: 정식기 | M35: 1 | Q35: Phoxim | R35: 1b
A36: 거세미나방류 | B36: 해충 | C36: 파프리카 | D36: 3 | E36: 싸이포스 | F36: 입제 | G36: 미보유 | H36: 등록 농약 | J36: 토양처리 | K36: 정식기 | M36: 1 | Q36: Cypermethrin+Tebupirimfos | R36: 3a+1b
A37: 과실파리류 | B37: 해충 | C37: 파프리카 | D37: 1 | E37: 모스피란 | F37: 수화제 | G37: 보유 | H37: 등록 농약 | I37: 2000 | J37: 경엽처리 | L37: 수확5일전 | M37: 3 | P37: 혼용 가능 살균제(경농 조회): 탄쟈비상 · 벨리스플러스 · 다놀라 · 벨쿠트 · 가스란 | Q37: 아세타미프리드 (Acetamiprid) | R37: 4a
A38: 과실파리류 | B38: 해충 | C38: 파프리카 | D38: 2 | E38: 동작그만 | F38: 유제 | G38: 보유 | H38: 등록 농약 | I38: 2000 | J38: 경엽처리 | L38: 수확2일전 | M38: 3 | Q38: 에마멕틴벤조에이트 (Emamectin benzoate) | R38: 6
A39: 과실파리류 | B39: 해충 | C39: 파프리카 | D39: 3 | E39: 델리게이트 | F39: 입상수화제 | G39: 보유 | H39: 등록 농약 | I39: 2000 | J39: 경엽처리 | L39: 수확2일전 | M39: 3 | Q39: 스피네토람 (Spinetoram) | R39: 5
A40: 과실파리류 | B40: 해충 | C40: 파프리카 | D40: 4 | E40: 뉴증원군 | F40: 유제 | G40: 보유 | H40: 등록 농약 | O40: 원본에 희석배수·사용방법·안전사용기준 미기재 | Q40: 비펜트린 (Bifenthrin) | R40: 3a
A41: 꽃노랑총채벌레 | B41: 해충 | C41: 파프리카 | D41: 1 | E41: 모스피란 | F41: 수화제 | G41: 보유 | H41: 등록 농약 | I41: 2000 | J41: 경엽처리 | L41: 수확5일전 | M41: 3 | P41: 혼용 가능 살균제(경농 조회): 탄쟈비상 · 벨리스플러스 · 다놀라 · 벨쿠트 · 가스란 | Q41: 아세타미프리드 (Acetamiprid) | R41: 4a
A42: 꽃노랑총채벌레 | B42: 해충 | C42: 파프리카 | D42: 2 | E42: 동작그만 | F42: 유제 | G42: 보유 | H42: 등록 농약 | I42: 2000 | J42: 경엽처리 | L42: 수확2일전 | M42: 3 | Q42: 에마멕틴벤조에이트 (Emamectin benzoate) | R42: 6
...

Sheet 전체 방제 정보
A1: 번호 | B1: 정보 구분 | C1: 작물명 | D1: 병해충 구분 | E1: 병해충명 | F1: 순위 | G1: 약제명 | H1: 제형 | I1: 학교 보유 | J1: 방제 구분 | K1: 희석배수 | L1: 살포 방법 | M1: 살포 시기 | N1: 수확 전 사용 제한 | O1: 최대 살포 횟수 | P1: 살포 간격 | Q1: 주의사항 | R1: 혼용 정보 | S1: 유효성분 | T1: 작용기작 | U1: 겸용 대상(전체) | V1: 혼용 상대 약제 | W1: 혼용 가능 여부 | X1: 방제가(효과) | Y1: 제조사·공시사업자 | Z1: 연락처 | AA1: 관련 정보 | AB1: 비고 | AC1: 공시번호 | AD1: 자재구분 | AE1: 자재명 | AF1: 가격(500mL) | AG1: 등재일자 | AH1: 공시 시작일 | AI1: 공시 종료일 | AJ1: 사업자등록번호 | AK1: 책임보험 가입여부 | AL1: 사업장/제조장 | AM1: 농약/비료 등록여부 | AN1: 약제명(원문) | AO1: 안전사용기준(원문) | AP1: 원본 위치 | AQ1: 출처 | AR1: 자료 조회일
A2: 1 | B2: 추천 약제(로테이션) | C2: 파프리카 | D2: 병해 | E2: 갈색무늬병 | F2: 1 | G2: 탄쟈비상 | H2: 액상수화제 | I2: 미보유 | J2: 등록 농약 | K2: 2000 | L2: 경엽처리 | N2: 수확3일전 | O2: 3 | Q2: 등록된 약제가 1개뿐이라 대체(로테이션)용은 없습니다. | R2: 모스피란과 혼용 가능(경농 조회) | S2: Trifloxystrobin | T2: 다3 | U2: 갈색무늬병, 갈색점무늬병, 탄저병 | AA2: 1순위 추천(원문): 탄쟈비상 (Trifloxystrobin) [학교 미보유 - 구매 필요] 2000배 희석 · 경엽처리 · 안전사용기준: 수확3일전 / 3회 | AN2: 탄쟈비상 (액상수화제) | AO2: 수확3일전/3회 | AP2: PART 1. 병해(살균제) > 갈색무늬병 로테이션표
A3: 2 | B3: 추천 약제(로테이션) | C3: 파프리카 | D3: 병해 | E3: 갈색점무늬병 | F3: 1 | G3: 버픽스 | H3: 액상수화제 | I3: 보유 | J3: 등록 농약 | K3: 2000 | L3: 경엽처리 | N3: 수확3일전 | O3: 3 | R3: 혼용정보 미확인 — 사용 전 제조사(동방아그로 1644-7337) 확인 | S3: Florylpicoxamid | T3: 다4 | U3: 갈색점무늬병, 잿빛곰팡이병, 탄저병 | AA3: 1순위 추천(원문): 버픽스 (Florylpicoxamid) [학교 보유 중] 2000배 희석 · 경엽처리 · 안전사용기준: 수확3일전 / 3회 | AN3: 버픽스(액상수화제) | AO3: 수확3일전 / 3회 | AP3: PART 1. 병해(살균제) > 갈색점무늬병 로테이션표
A4: 3 | B4: 추천 약제(로테이션) | C4: 파프리카 | D4: 병해 | E4: 갈색점무늬병 | F4: 2 | G4: 벨리스플러스 | H4: 입상수화제 | I4: 보유 | J4: 등록 농약 | K4: 2000 | L4: 경엽처리 | N4: 수확5일전 | O4: 2 | R4: 모스피란과 혼용 가능(경농 조회) | S4: Boscalid+Pyraclostrobin | T4: 다3,다2 | U4: 갈색점무늬병, 탄저병 | AN4: 벨리스플러스(입상수화제) | AO4: 수확5일전 / 2회 | AP4: PART 1. 병해(살균제) > 갈색점무늬병 로테이션표
A5: 4 | B5: 추천 약제(로테이션) | C5: 파프리카 | D5: 병해 | E5: 갈색점무늬병 | F5: 3 | G5: 오조아 | H5: 수화제 | I5: 미보유 | J5: 등록 농약 | K5: 2000 | L5: 경엽처리 | N5: 수확5일전 | O5: 4 | S5: Fluazinam | T5: 다5 | U5: 갈색점무늬병, 잿빛곰팡이병, 탄저병, 역병, 차먼지응애 | AN5: 오조아 (수화제) | AO5: 수확5일전 / 4회 | AP5: PART 1. 병해(살균제) > 갈색점무늬병 로테이션표
A6: 5 | B6: 추천 약제(로테이션) | C6: 파프리카 | D6: 병해 | E6: 갈색점무늬병 | F6: 4 | G6: 경탄 | H6: 액상수화제 | I6: 미보유 | J6: 등록 농약 | K6: 1000 | L6: 경엽처리 | N6: 수확3일전 | O6: 3 | S6: Chlorothalonil+Kresoxim-methyl | T6: 카,다3 | U6: 갈색점무늬병, 탄저병, 역병 | AN6: 경탄 (액상수화제) | AO6: 수확3일전 / 3회 | AP6: PART 1. 병해(살균제) > 갈색점무늬병 로테이션표
A7: 6 | B7: 추천 약제(로테이션) | C7: 파프리카 | D7: 병해 | E7: 붉은썩음병 | F7: 1 | G7: 스포르곤 | H7: 수화제 | I7: 미보유 | J7: 등록 농약 | K7: 1000 | L7: 관주처리 | N7: 수확7일전 | O7: 3 | R7: 모스피란 · 코니도 · 타스타와의 혼용 조합 자료 없음 | S7: Prochloraz-manganese | T7: 사1 | U7: 붉은썩음병, 뿌리썩음병, 탄저병, 흰가루병, 흰비단병 | AA7: 1순위 추천(원문): 스포르곤 (Prochloraz-manganese) [학교 미보유 - 구매 필요] 1000배 희석 · 관주처리 · 안전사용기준: 수확7일전 / 3회 | AN7: 스포르곤(수화제) | AO7: 수확7일전 / 3회 | AP7: PART 1. 병해(살균제) > 붉은썩음병 로테이션표
A8: 7 | B8: 추천 약제(로테이션) | C8: 파프리카 | D8: 병해 | E8: 붉은썩음병 | F8: 2 | G8: 균디스 | H8: 액상수화제 | I8: 미보유 | J8: 등록 농약 | K8: 4000 | L8: 관주처리 | N8: 수확3일전 | O8: 3 | S8: Azoxystrobin | T8: 다3 | U8: 붉은썩음병, 탄저병 | AN8: 균디스(액상수화제) | AO8: 수확3일전 / 3회 | AP8: PART 1. 병해(살균제) > 붉은썩음병 로테이션표
A9: 8 | B9: 추천 약제(로테이션) | C9: 파프리카 | D9: 병해 | E9: 뿌리썩음병 | F9: 1 | G9: 스포르곤 | H9: 입제 | I9: 미보유 | J9: 등록 농약 | K9: 1000 | L9: 관주처리 | N9: 수확7일전 | O9: 3 | Q9: 등록된 약제가 1개뿐이라 대체(로테이션)용은 없습니다. | R9: 모스피란 · 코니도 · 타스타와의 혼용 조합 자료 없음 | S9: Prochloraz-manganese | T9: 사1 | U9: 붉은썩음병, 뿌리썩음병, 탄저병 | AA9: 1순위 추천(원문): 스포르곤 (Prochloraz-manganese) [학교 미보유 - 구매 필요] 1000배 희석 · 관주처리 · 안전사용기준: 수확7일전 / 3회 | AN9: 스포르곤(입제) | AO9: 수확7일전 / 3회 | AP9: PART 1. 병해(살균제) > 뿌리썩음병 로테이션표
A10: 9 | B10: 추천 약제(로테이션) | C10: 파프리카 | D10: 병해 | E10: 세균점무늬병 | F10: 1 | G10: 무름반점뚝 | H10: 수화제 | I10: 보유 | J10: 등록 농약 | K10: 1000 | L10: 경엽처리 | N10: 수확7일전 | O10: 3 | R10: 혼용정보 미확인 — 사용 전 제조사(대유) 확인 | S10: Oxolinic acid | T10: 가4 | U10: 세균점무늬병 | AA10: 1순위 추천(원문): 무름반점뚝 (Oxolinic acid) [학교 보유 중] 1000배 희석 · 경엽처리 · 안전사용기준: 수확7일전 / 3회 | AN10: 무름반점뚝(수화제) | AO10: 수확7일전 / 3회 | AP10: PART 1. 병해(살균제) > 세균점무늬병 로테이션표
A11: 10 | B11: 추천 약제(로테이션) | C11: 파프리카 | D11: 병해 | E11: 세균점무늬병 | F11: 2 | G11: 미스타클린 | H11: 수화제 | I11: 보유 | J11: 등록 농약 | K11: 1000 | L11: 경엽처리 | N11: 수확3일전 | O11: 3 | S11: Oxytetracycline dihydrate+Validamycin A | T11: 라5+미분류(살균제) | U11: 세균점무늬병 | AN11: 미스타클린 수화제 | AO11: 수확3일전 / 3회 | AP11: PART 1. 병해(살균제) > 세균점무늬병 로테이션표
A12: 11 | B12: 추천 약제(로테이션) | C12: 파프리카 | D12: 병해 | E12: 세균점무늬병 | F12: 3 | G12: 가스란 | H12: 수화제 | I12: 미보유 | J12: 등록 농약 | K12: 1000 | L12: 경엽처리 | N12: 수확2일전 | O12: 5 | R12: 모스피란과 혼용 가능(경농 조회) | S12: 코퍼옥시클로라이드.가스가마이신 (Copper oxychloride+Kasugamycin) | T12: 라3,카 | U12: 세균점무늬병, 탄저병 | AN12: 가스란(수화제) | AO12: 수확2일전 / 5회 | AP12: PART 1. 병해(살균제) > 세균점무늬병 로테이션표
A13: 12 | B13: 추천 약제(로테이션) | C13: 파프리카 | D13: 병해 | E13: 세균점무늬병 | F13: 4 | G13: 골든벨 | H13: 액상수화제 | I13: 미보유 | J13: 등록 농약 | K13: 1000 | L13: 경엽처리 | N13: 수확2일전 | O13: 3 | S13: 가스가마이신.티오파네이트메틸 (Kasugamycin+Thiophanate-methyl) | T13: 나1,라3 | U13: 세균점무늬병, 탄저병 | AN13: 골든벨(액상수화제) | AO13: 수확2일전 / 3회 | AP13: PART 1. 병해(살균제) > 세균점무늬병 로테이션표
A14: 13 | B14: 추천 약제(로테이션) | C14: 파프리카 | D14: 병해 | E14: 잿빛곰팡이병 | F14: 1 | G14: 버픽스 | H14: 액상수화제 | I14: 보유 | J14: 등록 농약 | K14: 2000 | L14: 경엽처리 | N14: 수확3일전 | O14: 3 | R14: 혼용정보 미확인 — 사용 전 제조사(동방아그로 1644-7337) 확인 | S14: Florylpicoxamid | T14: 다4 | U14: 갈색점무늬병, 잿빛곰팡이병 | AA14: 1순위 추천(원문): 버픽스 (Florylpicoxamid) [학교 보유 중] 2000배 희석 · 경엽처리 · 안전사용기준: 수확3일전 / 3회 | AN14: 버픽스 (액상수화제) | AO14: 수확3일전 / 3회 | AP14: PART 1. 병해(살균제) > 잿빛곰팡이병 로테이션표
A15: 14 | B15: 추천 약제(로테이션) | C15: 파프리카 | D15: 병해 | E15: 잿빛곰팡이병 | F15: 2 | G15: 미래빛 | H15: 액상수화제 | I15: 보유 | J15: 등록 농약 | K15: 4000 | L15: 경엽처리 | N15: 수확3일전 | O15: 3 | S15: Pydiflumetofen | T15: 다2 | U15: 잿빛곰팡이병 | AN15: 미래빛 (액상수화제) | AO15: 수확3일전 / 3회 | AP15: PART 1. 병해(살균제) > 잿빛곰팡이병 로테이션표
A16: 15 | B16: 추천 약제(로테이션) | C16: 파프리카 | D16: 병해 | E16: 잿빛곰팡이병 | F16: 3 | G16: 사파이어 | H16: 액상수화제 | I16: 보유 | J16: 등록 농약 | K16: 2000 | L16: 경엽처리 | N16: 수확3일전 | O16: 2 | S16: Fludioxonil | T16: 마2 | U16: 잿빛곰팡이병 | AN16: 사파이어 (액상수화제) | AO16: 수확3일전 / 2회 | AP16: PART 1. 병해(살균제) > 잿빛곰팡이병 로테이션표
A17: 16 | B17: 추천 약제(로테이션) | C17: 파프리카 | D17: 병해 | E17: 잿빛곰팡이병 | F17: 4 | G17: 오조아 | H17: 수화제 | I17: 미보유 | J17: 등록 농약 | K17: 2000 | L17: 경엽처리 | N17: 수확5일전 | O17: 4 | S17: Fluazinam | T17: 다5 | U17: 갈색점무늬병, 잿빛곰팡이병, 탄저병 | AN17: 오조아 (수화제) | AO17: 수확5일전 / 4회 | AP17: PART 1. 병해(살균제) > 잿빛곰팡이병 로테이션표
A18: 17 | B18: 추천 약제(로테이션) | C18: 파프리카 | D18: 병해 | E18: 탄저병 | F18: 1 | G18: 벨리스플러스 | H18: 입상수화제 | I18: 보유 | J18: 등록 농약 | K18: 2000 | L18: 경엽처리 | N18: 수확5일전 | O18: 2 | R18: 모스피란과 혼용 가능(경농 조회) | S18: Boscalid+Pyraclostrobin | T18: 다3,다2 | U18: 역병, 잿빛곰팡이병, 갈색점무늬병, 탄저병 | AA18: 1순위 추천(원문): 벨리스플러스 (Boscalid+Pyraclostrobin) [학교 보유 중] 2000배 희석 · 경엽처리 · 안전사용기준: 수확5일전 / 2회 | AN18: 벨리스플러스(입상수화제) | AO18: 수확5일전 / 2회 | AP18: PART 1. 병해(살균제) > 탄저병 로테이션표
A19: 18 | B19: 추천 약제(로테이션) | C19: 파프리카 | D19: 병해 | E19: 탄저병 | F19: 2 | G19: 다놀라 | H19: 액상 | I19: 보유 | J19: 등록 농약 | Q19: 원본에 희석배수·사용방법·안전사용기준 미기재 | R19: 모스피란과 혼용 가능(경농 조회) | S19: 디페노코나졸.피라클로스트로빈 (Difenoconazole+Pyraclostrobin) | T19: 사1,다3 | U19: 탄저병 | AN19: 다놀라 (액상) | AO19: - | AP19: PART 1. 병해(살균제) > 탄저병 로테이션표
A20: 19 | B20: 추천 약제(로테이션) | C20: 파프리카 | D20: 병해 | E20: 탄저병 | F20: 3 | G20: 미리본 | I20: 보유 | J20: 등록 농약 | Q20: 원본에 희석배수·사용방법·안전사용기준 미기재 | S20: 플룩사피록사드.피라클로스트로빈 (Fluxapyroxad+Pyraclostrobin) | T20: 다3,다2 | U20: 탄저병 | AN20: 미리본 | AO20: - | AP20: PART 1. 병해(살균제) > 탄저병 로테이션표
A21: 20 | B21: 추천 약제(로테이션) | C21: 파프리카 | D21: 병해 | E21: 탄저병 | F21: 4 | G21: 벨쿠트 | H21: 수화제 | I21: 보유 | J21: 등록 농약 | Q21: 원본에 희석배수·사용방법·안전사용기준 미기재 | R21: 모스피란 · 코니도와 혼용 가능(경농·팜한농 조회) | S21: 이미녹타딘트리스알베실레이트 (Iminoctadin tris (albesilate)) | T21: 카 | U21: 탄저병, 잿빛곰팡이병 | AN21: 벨쿠트(수화제) | AO21: - | AP21: PART 1. 병해(살균제) > 탄저병 로테이션표
A22: 21 | B22: 추천 약제(로테이션) | C22: 파프리카 | D22: 병해 | E22: 풋마름병 | F22: 1 | G22: 크린쏘일 | H22: 입제 | I22: 미보유 | J22: 등록 농약 | L22: 토양처리 | M22: 정식 4주일 전 | O22: 1 | Q22: 가이드 추천문에는 유효성분 'Metam-sodium', 사용방법 '관주처리', 안전사용기준 '정식4주전 / 1회'(으)로 표기 — 원본 내 표기 상이, 확인 필요 | S22: Dazomet | T22: 미분류(살균제) | U22: 풋마름병 | AA22: 1순위 추천(원문): 크린쏘일 (Metam-sodium) [학교 미보유 - 구매 필요] 관주처리 · 안전사용기준: 정식4주전 / 1회 | AN22: 크린쏘일 (입제) | AO22: 정식기 / 1회 | AP22: PART 1. 병해(살균제) > 풋마름병 로테이션표
A23: 22 | B23: 추천 약제(로테이션) | C23: 파프리카 | D23: 해충 | E23: 거세미나방류 | F23: 1 | G23: 쏘버린 | H23: 입제 | I23: 미보유 | J23: 등록 농약 | L23: 토양처리 | M23: 정식기 | O23: 1 | R23: 정식 시 흙에 뿌리는 입제 — 혼용정보표 대상 아님 | S23: Carbosulfan | T23: 1a | U23: 거세미나방류, 꽃노랑총채벌레 | AA23: 1순위 추천(원문): 쏘버린 (Carbosulfan) [학교 미보유 - 구매 필요] 토양처리 · 안전사용기준: 정식기 / 1회 | AN23: 쏘버린 (입제) | AO23: 정식기 / 1회 | AP23: PART 2. 해충(살충제) > 거세미나방류 로테이션표
A24: 23 | B24: 추천 약제(로테이션) | C24: 파프리카 | D24: 해충 | E24: 거세미나방류 | F24: 2 | G24: 보라충 | H24: 입제 | I24: 미보유 | J24: 등록 농약 | L24: 토양처리 | M24: 정식기 | O24: 1 | S24: Phoxim | T24: 1b | U24: 거세미나방류 | AN24: 보라충 (입제) | AO24: 정식기 / 1회 | AP24: PART 2. 해충(살충제) > 거세미나방류 로테이션표
A25: 24 | B25: 추천 약제(로테이션) | C25: 파프리카 | D25: 해충 | E25: 거세미나방류 | F25: 3 | G25: 싸이포스 | H25: 입제 | I25: 미보유 | J25: 등록 농약 | L25: 토양처리 | M25: 정식기 | O25: 1 | S25: Cypermethrin+Tebupirimfos | T25: 3a+1b | U25: 거세미나방류 | AN25: 싸이포스 (입제) | AO25: 정식기 / 1회 | AP25: PART 2. 해충(살충제) > 거세미나방류 로테이션표
A26: 25 | B26: 추천 약제(로테이션) | C26: 파프리카 | D26: 해충 | E26: 과실파리류 | F26: 1 | G26: 모스피란 | H26: 수화제 | I26: 보유 | J26: 등록 농약 | K26: 2000 | L26: 경엽처리 | N26: 수확5일전 | O26: 3 | R26: 혼용 가능 살균제(경농 조회): 탄쟈비상 · 벨리스플러스 · 다놀라 · 벨쿠트 · 가스란 | S26: 아세타미프리드 (Acetamiprid) | T26: 4a | U26: 과실파리류, 꽃노랑총채벌레, 담배가루이, 복숭아혹진딧물, 목화진딧물 | AA26: 1순위 추천(원문): 모스피란 (아세타미프리드 (Acetamiprid)) [학교 보유 중] 2000배 희석 · 경엽처리 · 안전사용기준: 수확5일전 / 3회 | AN26: 모스피란 (수화제) | AO26: 수확5일전 / 3회 | AP26: PART 2. 해충(살충제) > 과실파리류 로테이션표
A27: 26 | B27: 추천 약제(로테이션) | C27: 파프리카 | D27: 해충 | E27: 과실파리류 | F27: 2 | G27: 동작그만 | H27: 유제 | I27: 보유 | J27: 등록 농약 | K27: 2000 | L27: 경엽처리 | N27: 수확2일전 | O27: 3 | S27: 에마멕틴벤조에이트 (Emamectin benzoate) | T27: 6 | U27: 과실파리류, 꽃노랑총채벌레, 담배가루이 | AN27: 동작그만 (유제) | AO27: 수확2일전 / 3회 | AP27: PART 2. 해충(살충제) > 과실파리류 로테이션표
A28: 27 | B28: 추천 약제(로테이션) | C28: 파프리카 | D28: 해충 | E28: 과실파리류 | F28: 3 | G28: 델리게이트 | H28: 입상수화제 | I28: 보유 | J28: 등록 농약 | K28: 2000 | L28: 경엽처리 | N28: 수확2일전 | O28: 3 | S28: 스피네토람 (Spinetoram) | T28: 5 | U28: 과실파리류, 꽃노랑총채벌레 | AN28: 델리게이트 (입상수화제) | AO28: 수확2일전 / 3회 | AP28: PART 2. 해충(살충제) > 과실파리류 로테이션표
A29: 28 | B29: 추천 약제(로테이션) | C29: 파프리카 | D29: 해충 | E29: 과실파리류 | F29: 4 | G29: 뉴증원군 | H29: 유제 | I29: 보유 | J29: 등록 농약 | Q29: 원본에 희석배수·사용방법·안전사용기준 미기재 | S29: 비펜트린 (Bifenthrin) | T29: 3a | U29: 과실파리류 | AN29: 뉴증원군 (유제) | AO29: - | AP29: PART 2. 해충(살충제) > 과실파리류 로테이션표
A30: 29 | B30: 추천 약제(로테이션) | C30: 파프리카 | D30: 해충 | E30: 꽃노랑총채벌레 | F30: 1 | G30: 모스피란 | H30: 수화제 | I30: 보유 | J30: 등록 농약 | K30: 2000 | L30: 경엽처리 | N30: 수확5일전 | O30: 3 | R30: 혼용 가능 살균제(경농 조회): 탄쟈비상 · 벨리스플러스 · 다놀라 · 벨쿠트 · 가스란 | S30: 아세타미프리드 (Acetamiprid) | T30: 4a | U30: 과실파리류, 꽃노랑총채벌레, 담배가루이, 복숭아혹진딧물 | AA30: 1순위 추천(원문): 모스피란 (아세타미프리드 (Acetamiprid)) [학교 보유 중] 2000배 희석 · 경엽처리 · 안전사용기준: 수확5일전 / 3회 | AN30: 모스피란 (수화제) | AO30: 수확5일전 / 3회 | AP30: PART 2. 해충(살충제) > 꽃노랑총채벌레 로테이션표
A31: 30 | B31: 추천 약제(로테이션) | C31: 파프리카 | D31: 해충 | E31: 꽃노랑총채벌레 | F31: 2 | G31: 동작그만 | H31: 유제 | I31: 보유 | J31: 등록 농약 | K31: 2000 | L31: 경엽처리 | N31: 수확2일전 | O31: 3 | S31: 에마멕틴벤조에이트 (Emamectin benzoate) | T31: 6 | U31: 과실파리류, 꽃노랑총채벌레, 담배가루이 | AN31: 동작그만 (유제) | AO31: 수확2일전 / 3회 | AP31: PART 2. 해충(살충제) > 꽃노랑총채벌레 로테이션표
A32: 31 | B32: 추천 약제(로테이션) | C32: 파프리카 | D32: 해충 | E32: 꽃노랑총채벌레 | F32: 3 | G32: 디져스 | H32: 유제 | I32: 보유 | J32: 등록 농약 | K32: 1000 | L32: 경엽처리 | N32: 수확2일전 | O32: 2 | S32: Fluxametamide+Pyrifluquinazon | T32: 30+9b | U32: 꽃노랑총채벌레, 담배가루이, 복숭아혹진딧물 | AN32: 디져스 (유제) | AO32: 수확2일전 / 2회 | AP32: PART 2. 해충(살충제) > 꽃노랑총채벌레 로테이션표
A33: 32 | B33: 추천 약제(로테이션) | C33: 파프리카 | D33: 해충 | E33: 꽃노랑총채벌레 | F33: 4 | G33: 강철비 | H33: 액상수화제 | I33: 보유 | J33: 등록 농약 | K33: 2000 | L33: 경엽처리 | N33: 수확2일전 | O33: 2 | R33: 혼용정보 미확인 — 사용 전 제조사(인바이오 031-477-6011) 확인 | S33: Chlorantraniliprole+Emamectin benzoate | T33: 28+6 | U33: 꽃노랑총채벌레, 차먼지응애 | AN33: 강철비 (액상수화제) | AO33: 수확2일전 / 2회 | AP33: PART 2. 해충(살충제) > 꽃노랑총채벌레 로테이션표
A34: 33 | B34: 추천 약제(로테이션) | C34: 파프리카 | D34: 해충 | E34: 담배가루이 | F34: 1 | G34: 모스피란 | H34: 수화제 | I34: 보유 | J34: 등록 농약 | K34: 2000 | L34: 경엽처리 | N34: 수확5일전 | O34: 3 | R34: 혼용 가능 살균제(경농 조회): 탄쟈비상 · 벨리스플러스 · 다놀라 · 벨쿠트 · 가스란 | S34: 아세타미프리드 (Acetamiprid) | T34: 4a | U34: 과실파리류, 꽃노랑총채벌레, 담배가루이, 복숭아혹진딧물 | AA34: 1순위 추천(원문): 모스피란 (아세타미프리드 (Acetamiprid)) [학교 보유 중] 2000배 희석 · 경엽처리 · 안전사용기준: 수확5일전 / 3회 | AN34: 모스피란 (수화제) | AO34: 수확5일전 / 3회 | AP34: PART 2. 해충(살충제) > 담배가루이 로테이션표
A35: 34 | B35: 추천 약제(로테이션) | C35: 파프리카 | D35: 해충 | E35: 담배가루이 | F35: 2 | G35: 동작그만 | H35: 유제 | I35: 보유 | J35: 등록 농약 | K35: 2000 | L35: 경엽처리 | N35: 수확2일전 | O35: 3 | S35: 에마멕틴벤조에이트 (Emamectin benzoate) | T35: 6 | U35: 과실파리류, 꽃노랑총채벌레, 담배가루이 | AN35: 동작그만 (유제) | AO35: 수확2일전 / 3회 | AP35: PART 2. 해충(살충제) > 담배가루이 로테이션표
A36: 35 | B36: 추천 약제(로테이션) | C36: 파프리카 | D36: 해충 | E36: 담배가루이 | F36: 3 | G36: 디져스 | H36: 유제 | I36: 보유 | J36: 등록 농약 | K36: 1000 | L36: 경엽처리 | N36: 수확2일전 | O36: 2 | S36: Fluxametamide+Pyrifluquinazon | T36: 30+9b | U36: 꽃노랑총채벌레, 담배가루이, 복숭아혹진딧물 | AN36: 디져스 (유제) | AO36: 수확2일전 / 2회 | AP36: PART 2. 해충(살충제) > 담배가루이 로테이션표
A37: 36 | B37: 추천 약제(로테이션) | C37: 파프리카 | D37: 해충 | E37: 담배가루이 | F37: 4 | G37: 산마루 | H37: 수화제 | I37: 보유 | J37: 등록 농약 | K37: 1000 | L37: 경엽처리 | N37: 수확3일전 | O37: 2 | S37: Pyridaben | T37: 21a | U37: 담배가루이, 차먼지응애 | AN37: 산마루 (수화제) | AO37: 수확3일전 / 2회 | AP37: PART 2. 해충(살충제) > 담배가루이 로테이션표
A38: 37 | B38: 추천 약제(로테이션) | C38: 파프리카 | D38: 해충 | E38: 복숭아혹진딧물 | F38: 1 | G38: 모스피란 | H38: 수화제 | I38: 보유 | J38: 등록 농약 | K38: 2000 | L38: 경엽처리 | N38: 수확5일전 | O38: 3 | R38: 혼용 가능 살균제(경농 조회): 탄쟈비상 · 벨리스플러스 · 다놀라 · 벨쿠트 · 가스란 | S38: 아세타미프리드 (Acetamiprid) | T38: 4a | U38: 과실파리류, 꽃노랑총채벌레, 담배가루이, 복숭아혹진딧물 | AA38: 1순위 추천(원문): 모스피란 (아세타미프리드 (Acetamiprid)) [학교 보유 중] 2000배 희석 · 경엽처리 · 안전사용기준: 수확5일전 / 3회 | AN38: 모스피란 (수화제) | AO38: 수확5일전 / 3회 | AP38: PART 2. 해충(살충제) > 복숭아혹진딧물 로테이션표
A39: 38 | B39: 추천 약제(로테이션) | C39: 파프리카 | D39: 해충 | E39: 복숭아혹진딧물 | F39: 2 | G39: 디져스 | H39: 유제 | I39: 보유 | J39: 등록 농약 | K39: 1000 | L39: 경엽처리 | N39: 수확2일전 | O39: 2 | S39: Fluxametamide+Pyrifluquinazon | T39: 30+9b | U39: 꽃노랑총채벌레, 담배가루이, 복숭아혹진딧물 | AN39: 디져스 (유제) | AO39: 수확2일전 / 2회 | AP39: PART 2. 해충(살충제) > 복숭아혹진딧물 로테이션표
A40: 39 | B40: 추천 약제(로테이션) | C40: 파프리카 | D40: 해충 | E40: 복숭아혹진딧물 | F40: 3 | G40: 기대찬 | H40: 입상수화제 | I40: 보유 | J40: 등록 농약 | K40: 2000 | L40: 경엽처리 | N40: 수확3일전 | O40: 2 | S40: Emamectin benzoate+Flonicamid | T40: 6+29 | U40: 꽃노랑총채벌레, 복숭아혹진딧물 | AN40: 기대찬 (입상수화제) | AO40: 수확3일전 / 2회 | AP40: PART 2. 해충(살충제) > 복숭아혹진딧물 로테이션표
...

Sheet 참고 사항
A1: ■ 사용 방법
A2: [병해충 방제 가이드] 시트 — 한눈에 보기
A3: ① 맨 위 노란 칸(병해충 선택)을 누르고 ▼ 목록에서 병해충을 고르면, 바로 아래에 1~4순위 약제와 희석배수·살포 방법·시기·횟수·주의사항이 표시됩니다.
A4: ② 아래 방제표에서 [병해충명] 머리글의 ▼ 필터 → 검색 칸에 병해충명 입력 → 확인. 해당 병해충의 약제만 남습니다.
A5: ③ 같은 병해충의 약제는 한 묶음(굵은 윗선 + 같은 바탕색)으로 표시되고, 순위 순서로 나열됩니다.
A6: [전체 방제 정보] 시트 — 원본 자료 전체(구매 필요 약제·유기농업자재 기타 효과·혼용 조합·확인결과 포함)를 모든 열에서 필터·검색할 수 있습니다.
A7: 새 자료 추가: [전체 방제 정보] 표 바로 아래 행에 입력하면 표가 자동 확장되고, 조회 카드에도 반영됩니다(정보 구분 = 추천 약제(로테이션)).
A8: 필터 해제: [데이터] 탭 → [지우기].
A10: ■ 표시 규칙
A11: • 노란색 = 학교(연암대) 보유 약제 • 주황 바탕 = 주의사항·혼용 정보가 있는 칸 • 초록 머리글 = 사용 방법(희석·방법·시기·횟수)
A12: • 원본에 값이 없는 칸은 빈칸으로 두었습니다(임의로 채우지 않음). 원본 "-" 표기도 빈칸입니다.
A13: • [살포 시기]는 원본에 시기가 명시된 경우(정식기·발생초기·생육기 등)만 기재했고, [수확 전 사용 제한]은 안전사용기준의 "수확○일전"입니다.
... A16: ■ 분류 값 목록 (드롭다운 원본 — 새 값이 필요하면 각 목록 아래 빈칸에 추가)
A17: 병해충(조회용) | B17: 정보 구분 | C17: 병해충 구분 | D17: 방제 구분 | E17: 학교 보유 | F17: 혼용 가능 여부 | G17: 제형 | H17: 살포 방법
A18: 갈색무늬병 | B18: 추천 약제(로테이션) | C18: 병해 | D18: 등록 농약 | E18: 보유 | F18: 가능 | G18: 수화제 | H18: 경엽처리
A19: 갈색점무늬병 | B19: 구매 필요 약제 | C19: 해충 | D19: 유기농업자재 | E19: 미보유 | F19: 조합 없음(섞지 말 것) | G19: 액상 | H19: 관주처리
A20: 붉은썩음병 | B20: 유기농업자재 | D20: 혼용정보 | F20: 미확인 | G20: 액상수화제 | H20: 관주처리(양액재배)
A21: 뿌리썩음병 | B21: 유기농업자재(기타 방제효과) | G21: 유제 | H21: 토양처리
A22: 세균점무늬병 | B22: 혼용 가능 조합 | G22: 입상수화제
A23: 잿빛곰팡이병 | B23: 혼용정보 확인결과 | G23: 입제
A24: 탄저병
A25: 풋마름병
A26: 거세미나방류
A27: 과실파리류
A28: 꽃노랑총채벌레
A29: 담배가루이
A30: 복숭아혹진딧물
A31: 온실가루이
A32: 진딧물(목화진딧물, 복숭아혹진딧물)
A33: 차먼지응애
A49: ■ 원본 가이드 안내·참고 사항 (원문 그대로)
A50: 번호 | B50: 원본 위치 | D50: 세부 위치 | H50: 내용 | I50: 자료 조회일
A51: 1 | B51: 개요 | H51: 파프리카 재배 현장 방제 가이드
A52: 2 | B52: 개요 | D52: 파프리카 재배 현장 방제 가이드 | H52: 연암대학교 스마트팜 유리온실
A53: 3 | B53: 개요 | D53: 파프리카 재배 현장 방제 가이드 | H53: 선정 기준: ① 학교 보유 약제 ② 여러 병해충에 겸용 가능한 약제
A54: 4 | B54: 개요 | D54: 파프리카 재배 현장 방제 가이드 | H54: 같은 작용기작(코드)을 연속 사용하면 저항성이 생기니, 2회 이상 살포 시 표의 2~4순위로 바꿔가며 로테이션
A55: 5 | B55: 개요 | D55: 구매 약제 전체 목록 (추천표 중 학교 미보유분) | H55: 총 14개 — 뒤쪽 병해충별 추천표에 나온 약제 중 현재 연암대 재고에 없는 것을 전부 모았습니다. 구매 시 참고하세요.
A56: 6 | B56: 개요 | D56: 구매 약제 전체 목록 (추천표 중 학교 미보유분) | H56: 유기농업자재 (친환경 공시자재)_보조 방제수단
A57: 7 | B57: PART 3. 유기농업자재 | H57: 선정 기준
A58: 8 | B58: PART 3. 유기농업자재 | H58: ① 이 가이드가 다루는 고추 병해충(꽃노랑총채벌레·온실가루이·복숭아혹진딧물)에 실제 방제시험 데이터가 있는 제품만
...
